Workbook

Sheet 填写首页
A1: 卫浴陶瓷报价填写首页
A2: 按顺序填写：① 必填信息 → ② 产品与成本 → ③ 看右侧结果；下方高级覆盖为空时，系统自动按参数计算。
A3: ① 必填信息 | E3: ② 产品与成本 | I3: ③ 自动结果
A4: * 客户名称 | C4: * 项目名称 | E4: * 马桶报价方式 | F4: 工厂本体成本直接填 | G4: * 工厂本体成本 RMB/件 | I4: 报价日期 | J4: =TODAY() | K4: 报价单号 | L4: QT-YYYYMMDD-001
A5: 销售负责人 | C5: * 型号编号 | E5: 手动装柜量 件/柜 | G5: * 柜型 | H5: 40HQ | I5: 报价币种售价 | J5: =IF(Input!$I$16="待填写","",Input!$I$6) | K5: 订单总额 | L5: =IF(Input!$I$16="待填写","",Input!$I$7)
A6: * 产品品类 | C6: * 订单数量 | E6: * 是否含盖板 | F6: 否 | G6: 盖板型号/备注 | I6: RMB 成本 | J6: =IF(Input!$I$16="待填写","",Input!$I$4) | K6: 报价币种成本 | L6: =IF(Input!$I$16="待填写","",Input!$I$5)
A7: * 目标市场 | C7: * 贸易条款 | E7: 盖板FOB进仓价 | G7: 水件FOB进仓价 | I7: 毛利率 | J7: =IF(Input!$I$16="待填写","",Input!$I$8) | K7: 报价结论 | L7: =IF(Input!$I$16="","待填写",Input!$I$16)
A8: * 装运港 | C8: * 目的港 | E8: 盖板档次 | G8: 铰链要求 | I8: 底线价 | J8: =IF(Input!$I$16="待填写","",Input!$I$9) | K8: 审批价 | L8: =IF(Input!$I$16="待填写","",Input!$I$10)
A9: * 报价币种 | B9: USD | C9: * 汇率 | E9: 铰链FOB进仓加价 | G9: 下水/安装件FOB进仓价 | I9: 装柜量 | J9: =IF(Input!$I$16="待填写","",Input!$I$11) | K9: 柜数 | L9: =IF(Input!$I$16="待填写","",Input!$I$12)
A10: * 有效期 | B10: 15 | C10: * MOQ | D10: 100 | E10: * 认证 | G10: 认证费用覆盖 | I10: 物流/件 | J10: =IF(Input!$I$16="待填写","",Input!$I$13) | K10: 目标毛利 | L10: =IF(Input!$I$16="待填写","",Input!$I$15)
A11: * 交期 | B11: 45 | C11: Incoterms | D11: Incoterms 2020 | E11: 冲水方式 | G11: 排污方式 | I11: 包装尺寸 | J11: =IF(Input!$I$16="待填写","",Input!$G$27) | K11: 装柜测算 | L11: =IF(Input!$I$16="待填写","",Input!$G$28)
A12: * 自产毛利 | B12: 0.3 | C12: * 外购毛利 | D12: 0.03 | E12: 坑距/墙排 | G12: 冲水量 | I12: 客户报价 | J12: CustomerQuote | K12: 内部核价 | L12: InternalCost
A13: * 底线毛利 | B13: 0 | C13: * 佣金预留 | D13: 0 | E13: * 含下水/安装件 | F13: 否 | G13: 安装方式 | I13: 自产毛利 | J13: =Input!$B$22 | K13: 外购毛利 | L13: =Input!$B$28
A14: * 售后预留 | B14: 0 | C14: * 汇率预留 | D14: 0 | E14: 龙头孔 | G14: 溢水孔 | I14: 综合毛利 | J14: =IF(Input!$I$16="待填写","",Input!$I$8) | K14: 底线毛利 | L14: =Input!$B$23
A15: * 经营费率 | B15: 0 | E15: * 产品长 mm | G15: * 产品宽 mm
E16: * 产品高 mm | G16: * 净重 KG | I16: 下一步
E17: * 每箱件数 | G17: 客户备注 | I17: 1 检查结果 | J17: 2 打印 CustomerQuote | K17: 3 内部看 InternalCost | L17: 4 旧表看 LegacyQuote
E18: 内部备注
A19: ④ 手动成本覆盖（可选；空白则自动计算）
A20: 包装材料 RMB/件 | C20: 生产人工 RMB/件 | E20: 包装人工 RMB/件 | G20: 损耗 RMB/件
A21: 模具/制造间接 | C21: 管理费 RMB/件 | E21: 物流 RMB/件 | G21: DDP报价 | H21: 专案核价
A22: 填写规则：红框/星号为必填；默认只需填本体成本、数量、市场、条款、港口、汇率、尺寸/装柜量。盖板/水件/下水件/铰链统一按FOB进仓价；手动覆盖填入后优先使用。
A23: 物流提示：EXW不计物流；FOB计中国端本地费；CFR/CIF再叠加目标市场海运/保险。DDP不自动报价。
A24: ⑤ 盖板独立包装/物流参考（可选，不计入报价）
A25: 盖板物流参考 | B25: 否 | C25: 盖板长 mm | E25: 盖板宽 mm | G25: 盖板高 mm
A26: 盖板净重 KG/套 | C26: 每箱套数 | D26: 10 | E26: 箱外扩 mm | F26: 15 | G26: 辅材 KG/箱 | H26: 1.2
A27: 纸板密度 KG/㎡ | B27: 0.65 | C27: 说明 | D27: FOB进仓价已含供应商包装/进仓成本；下方仅作体积/装柜参考，不计入报价。
A28: 盖板外箱尺寸 | B28: =IF(Packing!$B$55=0,"",TEXT(Packing!$B$52,"0")&" x "&TEXT(Packing!$B$53,"0")&" x "&TEXT(Packing!$B$54,"0")&" mm") | C28: 单箱 CBM | D28: =IF(Packing!$B$55=0,"",Packing!$B$55) | E28: 单箱毛重 KG | F28: =IF(Packing!$B$59=0,"",Packing!$B$59) | G28: 单套毛重 KG | H28: =IF(Packing!$B$60=0,"",Packing!$B$60)
A29: 盖板装柜量 | B29: =IF(Packing!$B$64=0,"",Packing!$B$64) | C29: 盖板柜数 | D29: =IF(Packing!$B$65=0,"",Packing!$B$65) | E29: 参考物流 RMB/套 | F29: =IF(Packing!$B$66=0,"",Packing!$B$66) | G29: 限制因素 | H29: =Packing!$B$68
A30: 报价处理 | B30: 不计入报价 | C30: 测算口径 | D30: 盖板独立包装/物流仅作装柜和体积参考；不重复计入BOM报价。

Sheet 检查项
A1: 报价检查项
A3: 检查项 | B3: 状态 | C3: 处理建议 | D3: 关联位置
A4: 资料完整性 | B4: =Input!$I$16 | C4: 待填写时先回填写首页补齐必填项 | D4: 填写首页 / Input
A5: 报价币种 | B5: =IF(OR(Input!$B$17="USD",Input!$B$17="RMB"),"OK","仅支持USD/RMB") | C5: EUR已移除，避免按USD汇率误报EUR | D5: 填写首页!B15
A6: DDP条款 | B6: =IF(Input!$B$13="DDP","禁止自动报价","OK") | C6: DDP需单独核关税、VAT、清关、尾程、仓储等 | D6: 填写首页!B11
A7: 主产品成本/装柜资料 | B7: =IF(Input!$G$44="是",IF(OR(N(Input!$B$11)<=0,N(Input!$E$45)<=0,AND(N(Input!$G$45)<=0,OR(Input!$E$22="",Input!$E$23="",Input!$E$24="",Input!$E$25="",Input!$E$26="",N(Input!$E$22)<=0,N(Input!$E$23)<=0,N(Input!$E$24)<=0,N(Input!$E$25)<=0,N(Input!$E$26)<=0))),"待补本体成本/装柜量","OK"),IF(OR(N(Input!$B$11)<=0,N(Input!$E$22)<=0,N(Input!$E$23)<=0,N(Input!$E$24)<=0,N(Input!$E$25)<=0,N(Input!$E$26)<=0),"待补正数","OK")) | C7: 成本模型需尺寸/重量/每箱件数；本体成本直填需工厂本体成本，并填手动装柜量或尺寸/重量用于物流 | D7: 填写首页!H4/F5 或 F15:F17/H15:H16
A8: 外购件价格口径 | B8: =IF(Input!$E$43="FOB进仓价","OK","检查口径") | C8: 盖板、水件、下水件、铰链统一填FOB进仓价/RMB | D8: 填写首页!B22:B23/D21:D23
A9: 盖板物流参考 | B9: =IF(AND(Input!$E$9="是",Input!$E$34="是",OR(N(Input!$E$35)<=0,N(Input!$E$36)<=0,N(Input!$E$37)<=0,N(Input!$E$38)<=0,N(Input!$E$39)<=0)),"仅参考待补","OK") | C9: FOB进仓价下不计入报价；如要看独立盖板装柜参考，再补尺寸/重量。 | D9: 填写首页!B29:H31
A10: 装柜经验复核 | B10: =IF(N(Input!$G$45)>0,"手动装柜量",IF(Packing!$B$36=0,"待补资料",IF(OR(Packing!$B$36<0.7*IFERROR(VLOOKUP(Input!$B$9,Library!$A$5:$L$10,12,FALSE),Packing!$B$36),Packing!$B$36>1.3*IFERROR(VLOOKUP(Input!$B$9,Library!$A$5:$L$10,12,FALSE),Packing!$B$36)),"需复核装柜量","OK"))) | C10: 动态装柜量偏离价格库经验值30%以上时复核；如填写首页F23手动装柜量，则以手动值为准。 | D10: Packing / Library
A11: 客户报价可外发 | B11: =IF(CustomerQuote!$B$12="","否","是") | C11: 否=资料不完整或条款被禁止自动报价 | D11: CustomerQuote!B12
A12: 马桶本体成本直填 | B12: =IF(Input!$G$44="是",IF(N(Input!$E$45)>0,"OK","待补本体成本"),"未启用") | C12: 启用工厂本体成本直接填时，填写首页H22必须大于0；包装、人工、损耗、间接费、物流另计或手动覆盖。 | D12: 填写首页!F4/H4/B20:F21
A13: 手动成本覆盖 | B13: =IF(SUM(N(Input!$E$47),N(Input!$G$47),N(Input!$E$48),N(Input!$G$48),N(Input!$E$49),N(Input!$G$49),N(Input!$E$50))>0,"已启用","未启用") | C13: 手动覆盖按RMB/件直接计入BOM；空白时使用自动参数。 | D13: 填写首页!B20:F21

Sheet Input
A1: 计算底表 Input - 日常只用第一个“填写首页”
A2: ① 黄色：必须填写 / 可改 | D2: ② 橙色：特殊报价才填 | F2: ③ 蓝灰：公式和系统参考 | H2: ④ 右侧：自动报价结果
A3: ① 客户与订单 | D3: ② 产品规格与配件 | H3: ③ 自动报价结果
A4: 报价日期 | B4: =IF(填写首页!J4="","",填写首页!J4) | D4: 字段 | E4: 请填这里 | F4: 系统参考 | G4: 特殊报价/备注 | H4: 报价基准成本 RMB/件 | I4: =IFERROR(BOM!F17,"")
A5: 报价单号 | B5: =填写首页!L4 | D5: 冲水方式 | E5: =IFERROR(IF(填写首页!F11="","",填写首页!F11),"") | H5: 报价币种成本/件 | I5: =IFERROR(BOM!F18,"")
A6: 客户名称 | B6: =IFERROR(IF(填写首页!B4="","",填写首页!B4),"") | D6: 排污方式 | E6: =IFERROR(IF(填写首页!H11="","",填写首页!H11),"") | H6: 报价币种销售价/件 | I6: =IFERROR(BOM!F19,"")
A7: 项目名称 | B7: =IFERROR(IF(填写首页!D4="","",填写首页!D4),"") | D7: 坑距/墙排 | E7: =IFERROR(IF(填写首页!F12="","",填写首页!F12),"") | H7: 订单总额 USD | I7: =IFERROR(I6*B11,"")
A8: 销售负责人 | B8: =IFERROR(IF(填写首页!B5="","",填写首页!B5),"") | D8: 冲水量 | E8: =IFERROR(IF(填写首页!H12="","",填写首页!H12),"") | H8: 当前净毛利率 | I8: =IFERROR(BOM!F22,"")
A9: 产品品类 | B9: =IFERROR(IF(填写首页!B6="","",填写首页!B6),"") | D9: 是否含盖板 | E9: =IFERROR(IF(填写首页!F6="","",填写首页!F6),"") | H9: 底线价 USD/件 | I9: =IFERROR(InternalCost!D11,"")
A10: 型号编号 | B10: =IFERROR(IF(填写首页!D5="","",填写首页!D5),"") | D10: 盖板型号/备注（不计价） | E10: =IFERROR(IF(填写首页!H6="","",填写首页!H6),"") | F10: =IFERROR(IF(E9="是",VLOOKUP(E11,Library!$N$34:$Q$39,3,FALSE),""),"") | G10: =IFERROR(IF(填写首页!B21="","",填写首页!B21),"") | H10: 审批价 USD/件 | I10: =IFERROR(InternalCost!B11,"")
A11: 订单数量 | B11: =IFERROR(IF(填写首页!D6="","",填写首页!D6),"") | D11: 盖板档次（必选） | E11: =IFERROR(IF(填写首页!F8="","",填写首页!F8),"") | F11: =IFERROR(IF(E9="是",VLOOKUP(E11,Library!$N$34:$Q$39,2,FALSE),0),0) | G11: =IFERROR(IF(填写首页!F7="","",填写首页!F7),"") | H11: 预估装柜量 | I11: =IFERROR(Tiers!B3,"")
A12: 目标市场 | B12: =IFERROR(IF(填写首页!B7="","",填写首页!B7),"") | D12: 铰链要求（必选） | E12: =IFERROR(IF(填写首页!H8="","",填写首页!H8),"") | F12: =IFERROR(IF(E9="是",VLOOKUP(E12,Library!$N$43:$Q$48,2,FALSE),0),0) | G12: =IFERROR(IF(填写首页!F9="","",填写首页!F9),"") | H12: 需要柜数 | I12: =IFERROR(Tiers!D3,"")
A13: 贸易条款 | B13: =IFERROR(IF(填写首页!D7="","",填写首页!D7),"") | D13: 盖板计价单价 | F13: =IFERROR(F11+F12,"") | G13: =IFERROR(IF(G11="",F11,G11)+IF(G12="",F12,G12),"") | H13: 条款物流 RMB/件 | I13: =IFERROR(BOM!F16,"")
A14: Incoterms | B14: =IFERROR(IF(填写首页!D11="","",填写首页!D11),"") | D14: 水件/五金参考 | F14: =IFERROR(IF(OR(Input!$B$9="分体马桶",Input!$B$9="连体马桶",Input!$B$9="挂墙马桶"),IFERROR(VLOOKUP(B9,Library!$A$5:$L$10,5,FALSE),0),0),"") | G14: =IFERROR(IF(填写首页!H7="","",填写首页!H7),"") | H14: 佣金/售后/汇率预留 RMB/件 | I14: =IFERROR(BOM!F20*(B24+B25+B26),"")
A15: 装运港 | B15: =IFERROR(IF(填写首页!B8="","",填写首页!B8),"") | D15: 水件/五金最终单价 | F15: =IFERROR(F14,"") | G15: =IFERROR(IF(G14="",F14,G14),"") | H15: 目标净毛利 RMB/件 | I15: =IFERROR(BOM!F21,"")
A16: 目的港 | B16: =IFERROR(IF(填写首页!D8="","",填写首页!D8),"") | D16: 安装方式（台盆） | E16: =IFERROR(IF(填写首页!H13="","",填写首页!H13),"") | H16: 报价结论 | I16: =InternalCost!$B$8
A17: 报价币种 | B17: =IFERROR(IF(填写首页!B9="","",填写首页!B9),"") | D17: 龙头孔（台盆） | E17: =IFERROR(IF(填写首页!F14="","",填写首页!F14),"") | H17: 客户版用途提醒 | I17: 只发客户版报价单，不发内部核价表
A18: 汇率 | B18: =IFERROR(IF(填写首页!D9="","",填写首页!D9),"") | D18: 溢水孔（台盆） | E18: =IFERROR(IF(填写首页!H14="","",填写首页!H14),"")
A19: 有效期（天） | B19: =IFERROR(IF(填写首页!B10="","",填写首页!B10),"") | D19: 是否含下水/安装件 | E19: =IFERROR(IF(填写首页!F13="","",填写首页!F13),"") | H19: 填写顺序
A20: MOQ（件） | B20: =IFERROR(IF(填写首页!D10="","",填写首页!D10),"") | D20: 下水/安装件参考 | F20: =IFERROR(IF(AND(OR(Input!$B$9="台上盆",Input!$B$9="台下盆",Input!$B$9="立柱盆/半柱盆"),E19="是"),IFERROR(VLOOKUP(B9,Library!$A$5:$L$10,6,FALSE),0),0),"") | G20: =IFERROR(IF(填写首页!H9="","",填写首页!H9),"") | H20: 1. 默认直接填工厂本体成本；人工/包装等在下方自动计算或手动覆盖。
A21: 交期（天） | B21: =IFERROR(IF(填写首页!B11="","",填写首页!B11),"") | D21: 下水/安装件最终单价 | F21: =IFERROR(F20,"") | G21: =IFERROR(IF(G20="",F20,G20),"") | H21: 2. 需要旧表口径时，填本体成本，并在⑦区填包装、人工、损耗、间接、物流覆盖。
A22: 自产目标毛利率 | B22: =IFERROR(IF(填写首页!B12="","",填写首页!B12),"") | D22: 产品长 mm | E22: =IFERROR(IF(填写首页!F15="","",填写首页!F15),"") | H22: 3. 蓝灰区域是自动公式，不要手动改。
A23: 底线净毛利率 | B23: =IFERROR(IF(填写首页!B13="","",填写首页!B13),"") | D23: 产品宽 mm | E23: =IFERROR(IF(填写首页!H15="","",填写首页!H15),"") | H23: 4. 给客户用 CustomerQuote，内部核价用 InternalCost。
A24: 佣金预留 | B24: =IFERROR(IF(填写首页!D13="","",填写首页!D13),"") | D24: 产品高 mm | E24: =IFERROR(IF(填写首页!F16="","",填写首页!F16),"") | H24: 5. 装柜量来自 Packing 自动测算。
A25: 售后风险预留 | B25: =IFERROR(IF(填写首页!B14="","",填写首页!B14),"") | D25: 净重 KG | E25: =IFERROR(IF(填写首页!H16="","",填写首页!H16),"")
A26: 汇率风险预留 | B26: =IFERROR(IF(填写首页!D14="","",填写首页!D14),"") | D26: 每箱件数 | E26: =IFERROR(IF(填写首页!F17="","",填写首页!F17),"")
A27: 经营费用率 | B27: =IFERROR(IF(填写首页!B15="","",填写首页!B15),"") | D27: 单件摊分体积 CBM | E27: =IFERROR(Packing!$B$22,"") | F27: 外箱尺寸 | G27: =IFERROR(TEXT(Packing!$B$18,"0")&" x "&TEXT(Packing!$B$19,"0")&" x "&TEXT(Packing!$B$20,"0")&" mm","")
A28: 外购目标毛利率 | B28: =IFERROR(IF(填写首页!D12="","",填写首页!D12),"") | D28: 单件摊分毛重 KG | E28: =IFERROR(Packing!$B$28,"") | F28: 装柜测算 | G28: =IFERROR(IF(N($G$45)>0,$G$45&" 件/柜，手动覆盖",Packing!$B$36&" 件/柜，"&Packing!$B$37),"")
D29: 柜型 | E29: =IFERROR(IF(填写首页!H5="","",填写首页!H5),"")
D30: 认证要求 | E30: =IFERROR(IF(填写首页!F10="","",填写首页!F10),"") | F30: =IFERROR(IF(E30="无",0,IFERROR(VLOOKUP(B9,Library!$A$5:$L$10,10,FALSE),0)),"") | G30: =IFERROR(IF(填写首页!H10="","",填写首页!H10),"")
D31: 客户备注 | E31: =IFERROR(IF(填写首页!H17="","",填写首页!H17),"")
D32: 内部备注 | E32: =IFERROR(IF(填写首页!F18="","",填写首页!F18),"")
D34: 盖板独立物流计入 | E34: 盖板物流仅参考 | F34: 盖板外箱尺寸 | G34: =IF(Packing!$B$55=0,"",TEXT(Packing!$B$52,"0")&" x "&TEXT(Packing!$B$53,"0")&" x "&TEXT(Packing!$B$54,"0")&" mm")
D35: 盖板长 mm | E35: =IF(填写首页!D25="","",填写首页!D25) | F35: 盖板单箱CBM | G35: =Packing!$B$55
D36: 盖板宽 mm | E36: =IF(填写首页!F25="","",填写首页!F25) | F36: 盖板单箱毛重 | G36: =Packing!$B$59
D37: 盖板高 mm | E37: =IF(填写首页!H25="","",填写首页!H25) | F37: 盖板单套毛重 | G37: =Packing!$B$60
D38: 盖板净重 KG/套 | E38: =IF(填写首页!B26="","",填写首页!B26) | F38: 盖板装柜量 | G38: =Packing!$B$64
D39: 盖板每箱套数 | E39: =IF(填写首页!D26="","",填写首页!D26) | F39: 盖板柜数 | G39: =Packing!$B$65
D40: 盖板箱外扩 mm | E40: =IF(填写首页!F26="","",填写首页!F26) | F40: 盖板参考物流RMB/套 | G40: =Packing!$B$66
D41: 盖板辅材 KG/箱 | E41: =IF(填写首页!H26="","",填写首页!H26) | F41: 盖板报价处理 | G41: 0
...

Sheet Library
A1: 价格库与默认参数
A2: 长期价格库：平时报价不要改；只有成本、物流、包装规则长期变化时再维护。
A3: 产品默认成本参数 | N3: 盖板成本
A4: 产品品类 | B4: 泥料系数 | C4: 泥料单价 | D4: 釉料成本 | E4: 水件/五金 | F4: 台盆下水/安装件 | G4: 直接人工 | H4: 外箱基础 | I4: 外箱CBM系数 | J4: 认证默认 | K4: 毛重外加KG | L4: 默认装柜量 | N4: 盖板档次 | O4: 参考单价 RMB | P4: 默认型号 | Q4: 备注
A5: 分体马桶 | B5: 0.92 | C5: 1.85 | D5: 16 | E5: 58 | F5: 0 | G5: 18 | H5: 8 | I5: 25 | J5: 4 | K5: 4.5 | L5: 520 | N5: PP 缓降 | O5: 48 | P5: SC-PP-001 | Q5: 常规出口
A6: 连体马桶 | B6: 0.94 | C6: 1.95 | D6: 20 | E6: 72 | F6: 0 | G6: 22 | H6: 10 | I6: 30 | J6: 5 | K6: 5.5 | L6: 430 | N6: UF 缓降 | O6: 78 | P6: SC-UF-001 | Q6: 中高端
A7: 挂墙马桶 | B7: 0.9 | C7: 2.05 | D7: 18 | E7: 45 | F7: 0 | G7: 16 | H7: 8 | I7: 25 | J7: 5 | K7: 4.5 | L7: 560 | N7: 薄盖快拆 | O7: 92 | P7: SC-SLIM-001 | Q7: 零售渠道
A8: 台上盆 | B8: 0.88 | C8: 1.75 | D8: 10 | E8: 0 | F8: 18 | G8: 8 | H8: 4 | I8: 18 | J8: 3 | K8: 2.5 | L8: 900
A9: 台下盆 | B9: 0.88 | C9: 1.75 | D9: 9 | E9: 0 | F9: 18 | G9: 7 | H9: 4 | I9: 16 | J9: 3 | K9: 2.2 | L9: 980 | N9: 铰链附加价
A10: 立柱盆/半柱盆 | B10: 0.9 | C10: 1.8 | D10: 14 | E10: 0 | F10: 28 | G10: 14 | H10: 7 | I10: 22 | J10: 4 | K10: 4 | L10: 620 | N10: 铰链要求 | O10: 附加价 RMB | P10: 默认说明 | Q10: 备注
N11: 常规缓降 | O11: 0 | P11: 标准配置
N12: 快拆缓降 | O12: 8 | P12: 快拆升级
A13: 贸易条款包含费用 | H13: 市场海运费用/柜 | N13: 金属铰链
A14: 条款 | B14: 出口本地 | C14: 海运 | D14: 保险 | E14: 目的地派送 | F14: 说明 | H14: 目标市场 | I14: 海运 USD/柜 | J14: 保险 RMB/柜 | K14: 目的地费用 RMB/柜 | N14: 柜型 | O14: 内陆/提货/进仓 | P14: 报关/单证 | Q14: 港杂/VGM/THC | R14: 商检/文件/其他
A15: EXW | B15: 0 | C15: 0 | D15: 0 | E15: 0 | F15: 工厂交货，通常不含出口费用 | H15: 美国 | I15: 2700 | J15: 10000 | K15: 0 | N15: 40HQ | O15: 5500 | P15: 1200 | Q15: 2500 | R15: 800
A16: FOB | B16: 1 | C16: 0 | D16: 0 | E16: 0 | F16: 含出口本地费用，到装运港船上交货 | H16: 欧洲 | I16: 2400 | J16: 380 | K16: 0 | N16: 40GP | O16: 5200 | P16: 1200 | Q16: 2300 | R16: 800
A17: CFR | B17: 1 | C17: 1 | D17: 0 | E17: 0 | F17: FOB + 海运 | H17: 中东 | I17: 2150 | J17: 320 | K17: 0 | N17: 20GP | O17: 4000 | P17: 1000 | Q17: 1800 | R17: 700
A18: CIF | B18: 1 | C18: 1 | D18: 1 | E18: 0 | F18: CFR + 保险 | H18: 亚洲 | I18: 1350 | J18: 220 | K18: 0
A19: DDP | B19: 1 | C19: 1 | D19: 1 | E19: 1 | F19: DDP需专案核价；Nigeria海运按USD/柜×汇率计入CFR/CIF | H19: 其他 | I19: 4200 | J19: 600 | K19: 0
H20: Nigeria | I20: 3500 | J20: 10000 | K20: 0
A21: 下拉选项维护区：填写首页的标准字段来自这里；新增选项后建议同步更新对应单元格下拉范围。
A22: 产品品类 | B22: 目标市场 | C22: 贸易条款 | D22: 报价币种 | E22: 柜型 | F22: 认证 | G22: 冲水方式 | H22: 排污方式 | I22: 坑距/墙排 | J22: 冲水量 | K22: 是否 | L22: 盖板档次 | M22: 铰链要求 | N22: 台盆安装方式 | O22: 龙头孔 | P22: 溢水孔 | Q22: 每箱件数 | R22: 常用装运港 | S22: 常用目的港 | T22: 盖板每箱套数 | U22: 盖板箱外扩mm
A23: 分体马桶 | B23: 美国 | C23: EXW | D23: USD | E23: 20GP | F23: 无 | G23: 虹吸 | H23: S-trap | I23: 180mm | J23: 3/4.5L | K23: 是 | L23: PP 普通 | M23: 常规 | N23: 台上 | O23: 无孔 | P23: 有 | Q23: 1 | R23: Xiamen | S23: Los Angeles | T23: 5 | U23: 10
A24: 连体马桶 | B24: 欧洲 | C24: FOB | D24: RMB | E24: 40GP | F24: UPC | G24: 冲落 | H24: P-trap | I24: 250mm | J24: 3/6L | K24: 否 | L24: PP 缓降 | M24: 常规缓降 | N24: 台下 | O24: 单孔 | P24: 无 | Q24: 2 | R24: Ningbo | S24: Long Beach | T24: 10 | U24: 15
A25: 挂墙马桶 | B25: 中东 | C25: CFR | E25: 40HQ | F25: cUPC | G25: 喷射虹吸 | H25: 墙排 | I25: 300mm | J25: 4.8L | L25: UF 缓降 | M25: 快拆缓降 | N25: 立柱 | O25: 三孔 | Q25: 4 | R25: Shanghai | S25: New York | T25: 20 | U25: 20
A26: 台上盆 | B26: 亚洲 | C26: CIF | F26: WaterSense | G26: 旋涡虹吸 | I26: 305mm | J26: 6L | L26: UF 快拆 | M26: 不锈钢铰链 | N26: 半柱 | O26: 可定制 | Q26: 6 | R26: Shenzhen | S26: Hamburg | T26: 30
A27: 台下盆 | B27: 其他 | F27: CE | G27: 双冲 | I27: 400mm | J27: 1.28GPF | L27: 薄盖快拆 | M27: 锌合金铰链 | N27: 挂墙 | R27: Qingdao | S27: Rotterdam | T27: 50
A28: 立柱盆/半柱盆 | B28: Nigeria | F28: UKCA | I28: 墙排 | J28: 1.6GPF | L28: 智能盖板 | R28: Guangzhou | S28: Jebel Ali
F29: WRAS | R29: Nigeria | S29: Riyadh
F30: SASO | S30: Singapore
F31: 其他 | S31: Lagos-Apapa
S32: Tin Can Island
N33: 盖板档次 | O33: FOB进仓价 RMB | P33: 默认型号 | Q33: 备注 | S33: Onne
N34: PP 普通 | O34: 38 | P34: SC-PP-STD-001 | Q34: 经济款，非缓降 | S34: Port Harcourt
N35: PP 缓降 | O35: 48 | P35: SC-PP-001 | Q35: 常规出口 | S35: Calabar
N36: UF 缓降 | O36: 78 | P36: SC-UF-001 | Q36: 中高端 | S36: Lekki
N37: UF 快拆 | O37: 86 | P37: SC-UF-QD-001 | Q37: 快拆升级
N38: 薄盖快拆 | O38: 92 | P38: SC-SLIM-001 | Q38: 薄盖/快拆
N39: 智能盖板 | O39: 380 | P39: SC-SMART-001 | Q39: 功能差异大，接单前需复核
N42: 铰链要求 | O42: FOB进仓加价 RMB | P42: 默认说明 | Q42: 备注
...

Sheet BOM
A1: BOM 核价表（内部）
A2: 自动核价页：不要改公式；临时特殊价格在 Input 橙色格填写，长期价格去 Library 维护。
A3: 说明：黄色单价/参数可按特殊订单调整；灰色公式自动计算。不要把本表直接发给客户。
A4: 成本层级 | B4: 项目 | C4: 单位 | D4: 数量/件 | E4: 单价/参数 | F4: RMB/件 | G4: 订单总额 RMB | H4: 备注
A5: 材料 | B5: 陶瓷本体/工厂本体成本 | C5: KG | D5: =IFERROR(IF(AND(Input!$G$44="是",N(Input!$E$45)>0),1,Input!$E$25*IFERROR(VLOOKUP(Input!$B$9,Library!$A$5:$L$10,2,FALSE),0)),"") | E5: =IFERROR(IF(AND(Input!$G$44="是",N(Input!$E$45)>0),Input!$E$45,VLOOKUP(Input!$B$9,Library!$A$5:$L$10,3,FALSE)),0) | F5: =IFERROR(IF(AND(Input!$G$44="是",N(Input!$E$45)>0),Input!$E$45,D5*E5),0) | G5: =IFERROR(F5*Input!$B$11,0) | H5: 成本模型：净重×泥料系数×泥料单价；直接填：只替代马桶/陶瓷本体VC cost
A6: 材料 | B6: 釉料 | C6: 件 | D6: =IFERROR(IF(AND(Input!$G$44="是",N(Input!$E$45)>0),0,1),"") | E6: =IFERROR(IF(AND(Input!$G$44="是",N(Input!$E$45)>0),0,VLOOKUP(Input!$B$9,Library!$A$5:$L$10,4,FALSE)),0) | F6: =IFERROR(D6*E6,0) | G6: =IFERROR(F6*Input!$B$11,0) | H6: 直接填本体成本时，釉料视为已包含在本体VC cost中
A7: 配件 | B7: 水件/五金 | C7: 套 | D7: =IFERROR(IF(OR(Input!$B$9="分体马桶",Input!$B$9="连体马桶",Input!$B$9="挂墙马桶"),IF(Input!$G$44="是",IF(N(Input!$G$14)>0,1,0),1),0),"") | E7: =IFERROR(IF(Input!$G$44="是",Input!$G$14,Input!$G$15),"") | F7: =IFERROR(D7*E7,0) | G7: =IFERROR(F7*Input!$B$11,0) | H7: 成本模型自动带入水件/五金；直接填模式仅在填写首页D21手动填FOB进仓价时另计
A8: 配件 | B8: 盖板 | C8: 套 | D8: =IFERROR(IF(AND(OR(Input!$B$9="分体马桶",Input!$B$9="连体马桶",Input!$B$9="挂墙马桶"),Input!$E$9="是"),IF(Input!$G$44="是",IF(N(Input!$G$11)+N(Input!$G$12)>0,1,0),1),0),"") | E8: =IFERROR(IF(Input!$G$44="是",N(Input!$G$11)+N(Input!$G$12),Input!$G$13),"") | F8: =IFERROR(D8*E8,0) | G8: =IFERROR(F8*Input!$B$11,0) | H8: 成本模型按盖板档次/铰链计价；直接填模式仅在B22/B23填FOB进仓价时另计
A9: 配件 | B9: 台盆下水/安装件 | C9: 套 | D9: =IFERROR(IF(AND(OR(Input!$B$9="台上盆",Input!$B$9="台下盆",Input!$B$9="立柱盆/半柱盆"),Input!$E$19="是"),1,0),"") | E9: =IFERROR(Input!$G$21,"") | F9: =IFERROR(D9*E9,0) | G9: =IFERROR(F9*Input!$B$11,0) | H9: 台盆下水/安装件最终单价来自 Input!G20，可手动覆盖
A10: 包装 | B10: 包装材料 | C10: 件 | D10: =IFERROR(1,"") | E10: =IFERROR(IF(N(Input!$E$47)>0,Input!$E$47,2+6+VLOOKUP(Input!$B$9,Library!$A$5:$L$10,8,FALSE)+Input!$E$27*IFERROR(VLOOKUP(Input!$B$9,Library!$A$5:$L$10,9,FALSE),0)),0) | F10: =IFERROR(D10*E10,0) | G10: =IFERROR(F10*Input!$B$11,0) | H10: 包装材料另计；可在填写首页B37手动覆盖，空白则自动估算
A11: 认证 | B11: 认证/测试摊销 | C11: 件 | D11: =IFERROR(IF(Input!$E$30="无",0,1),"") | E11: =IFERROR(IF(Input!$G$30="",Input!$F$30,Input!$G$30),"") | F11: =IFERROR(D11*E11,0) | G11: =IFERROR(F11*Input!$B$11,0) | H11: 认证参考价来自价格库，可在 Input!G30 手动覆盖
A12: 人工 | B12: 直接人工 | C12: 件 | D12: =IFERROR(1,"") | E12: =IFERROR(IF(OR(N(Input!$G$47)>0,N(Input!$E$48)>0),N(Input!$G$47)+N(Input!$E$48),VLOOKUP(Input!$B$9,Library!$A$5:$L$10,7,FALSE)),0) | F12: =IFERROR(D12*E12,0) | G12: =IFERROR(F12*Input!$B$11,0) | H12: 人工另计；可填生产人工D37和包装人工F37覆盖，空白则按品类默认人工
A13: 制造 | B13: 制造间接/模具分摊 | C13: 率 | D13: 1 | E13: 0.03 | F13: =IFERROR(IF(N(Input!$E$49)>0,Input!$E$49,(SUM(F5:F6)+F12)*E13),0) | G13: =IFERROR(F13*Input!$B$11,0) | H13: 模具/制造间接另计；可在填写首页B38手动覆盖
A14: 损耗 | B14: 低合格率/破损预留 | C14: 率 | D14: 1 | E14: 0.05 | F14: =IFERROR(IF(N(Input!$G$48)>0,Input!$G$48,(SUM(F5:F6)+F10+F12)*E14),0) | G14: =IFERROR(F14*Input!$B$11,0) | H14: 损耗另计；可在填写首页H37手动覆盖
A15: 间接 | B15: 经营/管理间接费 | C15: 率 | D15: 1 | E15: =IFERROR(Input!$B$27,"") | F15: =IFERROR(IF(N(Input!$G$49)>0,Input!$G$49,SUM(F5:F14)*E15),0) | G15: =IFERROR(F15*Input!$B$11,0) | H15: 管理费/经营间接另计；可在填写首页D38手动覆盖，空白则按经营费率
A16: 物流 | B16: 当前条款物流 | C16: 件 | D16: =IFERROR(1,"") | E16: =IFERROR(IF(N(Input!$E$50)>0,Input!$E$50,IFERROR(IF(Input!$B$11>0,((IFERROR(VLOOKUP(Input!$E$29,Library!$N$15:$R$17,2,FALSE)+VLOOKUP(Input!$E$29,Library!$N$15:$R$17,3,FALSE)+VLOOKUP(Input!$E$29,Library!$N$15:$R$17,4,FALSE)+VLOOKUP(Input!$E$29,Library!$N$15:$R$17,5,FALSE),0))*Tiers!$D$3*IFERROR(VLOOKUP(Input!$B$13,Library!$A$15:$F$19,2,FALSE),0)+(IFERROR(VLOOKUP(Input!$B$12,Library!$H$15:$K$20,2,FALSE)*Input!$B$18,0))*Tiers!$D$3*IFERROR(VLOOKUP(Input!$B$13,Library!$A$15:$F$19,3,FALSE),0)+(IFERROR(VLOOKUP(Input!$B$12,Library!$H$15:$K$20,3,FALSE),0))*Tiers!$D$3*IFERROR(VLOOKUP(Input!$B$13,Library!$A$15:$F$19,4,FALSE),0)+(IFERROR(VLOOKUP(Input!$B$12,Library!$H$15:$K$20,4,FALSE),0))*Tiers!$D$3*IFERROR(VLOOKUP(Input!$B$13,Library!$A$15:$F$19,5,FALSE),0))/Input!$B$11,0),0)),0) | F16: =IFERROR(D16*E16,0) | G16: =IFERROR(F16*Input!$B$11,0) | H16: 物流另计；可在填写首页F38手动覆盖，空白则按条款/市场/装柜量自动计算
A17: 合计 | B17: 报价基准成本 | C17: 件 | F17: =IFERROR(SUM(F5:F16),0) | G17: =IFERROR(F17*Input!$B$11,0) | H17: 本体成本 + 可选外购件 + 包装 + 人工 + 损耗 + 间接费 + 当前条款物流
A18: 换算 | B18: 报价币种成本 | C18: 件 | F18: =IFERROR(IF(Input!$B$17="RMB",F17,IF(Input!$B$18>0,F17/Input!$B$18,0)),0) | G18: =IFERROR(F18*Input!$B$11,0) | H18: RMB 成本按报价币种汇率换算；RMB 报价不换算
A19: 报价 | B19: 报价币种销售价 | C19: 件 | F19: =IFERROR(IF(Input!$B$17="RMB",F20,IF(Input!$B$18>0,F20/Input!$B$18,0)),0) | G19: =IFERROR(F19*Input!$B$11,0) | H19: 按自产毛利30%默认、外购毛利3%默认和手动覆盖/自动成本反推报价币种销售价
A20: 报价 | B20: RMB 销售价 | C20: 件 | F20: =IFERROR(IF(AND(1-Input!$B$22>0,1-Input!$B$28>0,1-(Input!$B$24+Input!$B$25+Input!$B$26)>0,1-Input!$B$23>0),MAX((((SUM(F5:F6)+SUM(F12:F15))/(1-Input!$B$22))+(SUM(F7:F11)/(1-Input!$B$28))+F16)/(1-(Input!$B$24+Input!$B$25+Input!$B$26)),((F17/(1-Input!$B$23))/(1-(Input!$B$24+Input!$B$25+Input!$B$26)))),0),0) | G20: =IFERROR(F20*Input!$B$11,0) | H20: 按报价币种反推前的 RMB 销售价；底线毛利约束已纳入
A21: 利润 | B21: 目标净毛利 | C21: 件 | F21: =IFERROR(F20-F17-F20*(Input!$B$24+Input!$B$25+Input!$B$26),0) | G21: =IFERROR(F21*Input!$B$11,0) | H21: 销售价 - 成本 - 佣金/售后/汇率预留
A22: 利润 | B22: 当前净毛利率 | C22: 率 | F22: =IFERROR(F21/F20,0) | H22: 目标净毛利 / RMB 销售价

Sheet Tiers
A1: 数量阶梯报价
A2: 自动数量阶梯页：只看结果；柜数和物流根据 Packing 动态装柜量自动重算。
A3: 当前动态装柜量 | B3: =IFERROR(IF(N(Input!$G$45)>0,Input!$G$45,Packing!$B$36),"") | C3: 当前订单柜数 | D3: =IFERROR(MAX(1,ROUNDUP(Input!$B$11/MAX($B$3,1),0)),"") | E3: 说明 | F3: 手动装柜量优先；为空时按Packing自动测算
A4: 当前订单数量 | B4: =IFERROR(Input!$B$11,"") | C4: 贸易条款 | D4: =IFERROR(Input!$B$13,"") | E4: 装运港/目的港 | F4: =IFERROR(Input!$B$15&" / "&Input!$B$16,"")
A6: 数量档 | B6: 柜数 | C6: 条款物流 RMB/件 | D6: 报价基准成本 RMB/件 | E6: 报价币种报价/件 | F6: 订单总额 | G6: 备注
A7: 100 | B7: =IFERROR(MAX(1,ROUNDUP(A7/MAX($B$3,1),0)),"") | C7: =IFERROR(IF(A7>0,((IFERROR(VLOOKUP(Input!$E$29,Library!$N$15:$R$17,2,FALSE)+VLOOKUP(Input!$E$29,Library!$N$15:$R$17,3,FALSE)+VLOOKUP(Input!$E$29,Library!$N$15:$R$17,4,FALSE)+VLOOKUP(Input!$E$29,Library!$N$15:$R$17,5,FALSE),0))*B7*IFERROR(VLOOKUP(Input!$B$13,Library!$A$15:$F$19,2,FALSE),0)+(IFERROR(VLOOKUP(Input!$B$12,Library!$H$15:$K$20,2,FALSE)*Input!$B$18,0))*B7*IFERROR(VLOOKUP(Input!$B$13,Library!$A$15:$F$19,3,FALSE),0)+(IFERROR(VLOOKUP(Input!$B$12,Library!$H$15:$K$20,3,FALSE),0))*B7*IFERROR(VLOOKUP(Input!$B$13,Library!$A$15:$F$19,4,FALSE),0)+(IFERROR(VLOOKUP(Input!$B$12,Library!$H$15:$K$20,4,FALSE),0))*B7*IFERROR(VLOOKUP(Input!$B$13,Library!$A$15:$F$19,5,FALSE),0))/A7,0),0) | D7: =IFERROR(BOM!$F$17-BOM!$F$16+C7,"") | E7: =IFERROR(IF(CustomerQuote!$B$12="","",IF(Input!$B$17="RMB",MAX((((SUM(BOM!$F$5:$F$6)+SUM(BOM!$F$12:$F$15))/(1-Input!$B$22))+(SUM(BOM!$F$7:$F$11)/(1-Input!$B$28))+C7)/(1-(Input!$B$24+Input!$B$25+Input!$B$26)),D7/(1-Input!$B$23)/(1-(Input!$B$24+Input!$B$25+Input!$B$26))),MAX((((SUM(BOM!$F$5:$F$6)+SUM(BOM!$F$12:$F$15))/(1-Input!$B$22))+(SUM(BOM!$F$7:$F$11)/(1-Input!$B$28))+C7)/(1-(Input!$B$24+Input!$B$25+Input!$B$26)),D7/(1-Input!$B$23)/(1-(Input!$B$24+Input!$B$25+Input!$B$26)))/Input!$B$18)),"") | F7: =IFERROR(E7*A7,"") | G7: =IFERROR(Input!$B$13&" "&IF(OR(Input!$B$13="CFR",Input!$B$13="CIF"),Input!$B$16,Input!$B$15)&", "&Input!$B$14,"")
A8: 300 | B8: =IFERROR(MAX(1,ROUNDUP(A8/MAX($B$3,1),0)),"") | C8: =IFERROR(IF(A8>0,((IFERROR(VLOOKUP(Input!$E$29,Library!$N$15:$R$17,2,FALSE)+VLOOKUP(Input!$E$29,Library!$N$15:$R$17,3,FALSE)+VLOOKUP(Input!$E$29,Library!$N$15:$R$17,4,FALSE)+VLOOKUP(Input!$E$29,Library!$N$15:$R$17,5,FALSE),0))*B8*IFERROR(VLOOKUP(Input!$B$13,Library!$A$15:$F$19,2,FALSE),0)+(IFERROR(VLOOKUP(Input!$B$12,Library!$H$15:$K$20,2,FALSE)*Input!$B$18,0))*B8*IFERROR(VLOOKUP(Input!$B$13,Library!$A$15:$F$19,3,FALSE),0)+(IFERROR(VLOOKUP(Input!$B$12,Library!$H$15:$K$20,3,FALSE),0))*B8*IFERROR(VLOOKUP(Input!$B$13,Library!$A$15:$F$19,4,FALSE),0)+(IFERROR(VLOOKUP(Input!$B$12,Library!$H$15:$K$20,4,FALSE),0))*B8*IFERROR(VLOOKUP(Input!$B$13,Library!$A$15:$F$19,5,FALSE),0))/A8,0),0) | D8: =IFERROR(BOM!$F$17-BOM!$F$16+C8,"") | E8: =IFERROR(IF(CustomerQuote!$B$12="","",IF(Input!$B$17="RMB",MAX((((SUM(BOM!$F$5:$F$6)+SUM(BOM!$F$12:$F$15))/(1-Input!$B$22))+(SUM(BOM!$F$7:$F$11)/(1-Input!$B$28))+C8)/(1-(Input!$B$24+Input!$B$25+Input!$B$26)),D8/(1-Input!$B$23)/(1-(Input!$B$24+Input!$B$25+Input!$B$26))),MAX((((SUM(BOM!$F$5:$F$6)+SUM(BOM!$F$12:$F$15))/(1-Input!$B$22))+(SUM(BOM!$F$7:$F$11)/(1-Input!$B$28))+C8)/(1-(Input!$B$24+Input!$B$25+Input!$B$26)),D8/(1-Input!$B$23)/(1-(Input!$B$24+Input!$B$25+Input!$B$26)))/Input!$B$18)),"") | F8: =IFERROR(E8*A8,"") | G8: =IFERROR(Input!$B$13&" "&IF(OR(Input!$B$13="CFR",Input!$B$13="CIF"),Input!$B$16,Input!$B$15)&", "&Input!$B$14,"")
A9: 500 | B9: =IFERROR(MAX(1,ROUNDUP(A9/MAX($B$3,1),0)),"") | C9: =IFERROR(IF(A9>0,((IFERROR(VLOOKUP(Input!$E$29,Library!$N$15:$R$17,2,FALSE)+VLOOKUP(Input!$E$29,Library!$N$15:$R$17,3,FALSE)+VLOOKUP(Input!$E$29,Library!$N$15:$R$17,4,FALSE)+VLOOKUP(Input!$E$29,Library!$N$15:$R$17,5,FALSE),0))*B9*IFERROR(VLOOKUP(Input!$B$13,Library!$A$15:$F$19,2,FALSE),0)+(IFERROR(VLOOKUP(Input!$B$12,Library!$H$15:$K$20,2,FALSE)*Input!$B$18,0))*B9*IFERROR(VLOOKUP(Input!$B$13,Library!$A$15:$F$19,3,FALSE),0)+(IFERROR(VLOOKUP(Input!$B$12,Library!$H$15:$K$20,3,FALSE),0))*B9*IFERROR(VLOOKUP(Input!$B$13,Library!$A$15:$F$19,4,FALSE),0)+(IFERROR(VLOOKUP(Input!$B$12,Library!$H$15:$K$20,4,FALSE),0))*B9*IFERROR(VLOOKUP(Input!$B$13,Library!$A$15:$F$19,5,FALSE),0))/A9,0),0) | D9: =IFERROR(BOM!$F$17-BOM!$F$16+C9,"") | E9: =IFERROR(IF(CustomerQuote!$B$12="","",IF(Input!$B$17="RMB",MAX((((SUM(BOM!$F$5:$F$6)+SUM(BOM!$F$12:$F$15))/(1-Input!$B$22))+(SUM(BOM!$F$7:$F$11)/(1-Input!$B$28))+C9)/(1-(Input!$B$24+Input!$B$25+Input!$B$26)),D9/(1-Input!$B$23)/(1-(Input!$B$24+Input!$B$25+Input!$B$26))),MAX((((SUM(BOM!$F$5:$F$6)+SUM(BOM!$F$12:$F$15))/(1-Input!$B$22))+(SUM(BOM!$F$7:$F$11)/(1-Input!$B$28))+C9)/(1-(Input!$B$24+Input!$B$25+Input!$B$26)),D9/(1-Input!$B$23)/(1-(Input!$B$24+Input!$B$25+Input!$B$26)))/Input!$B$18)),"") | F9: =IFERROR(E9*A9,"") | G9: =IFERROR(Input!$B$13&" "&IF(OR(Input!$B$13="CFR",Input!$B$13="CIF"),Input!$B$16,Input!$B$15)&", "&Input!$B$14,"")
A10: 1000 | B10: =IFERROR(MAX(1,ROUNDUP(A10/MAX($B$3,1),0)),"") | C10: =IFERROR(IF(A10>0,((IFERROR(VLOOKUP(Input!$E$29,Library!$N$15:$R$17,2,FALSE)+VLOOKUP(Input!$E$29,Library!$N$15:$R$17,3,FALSE)+VLOOKUP(Input!$E$29,Library!$N$15:$R$17,4,FALSE)+VLOOKUP(Input!$E$29,Library!$N$15:$R$17,5,FALSE),0))*B10*IFERROR(VLOOKUP(Input!$B$13,Library!$A$15:$F$19,2,FALSE),0)+(IFERROR(VLOOKUP(Input!$B$12,Library!$H$15:$K$20,2,FALSE)*Input!$B$18,0))*B10*IFERROR(VLOOKUP(Input!$B$13,Library!$A$15:$F$19,3,FALSE),0)+(IFERROR(VLOOKUP(Input!$B$12,Library!$H$15:$K$20,3,FALSE),0))*B10*IFERROR(VLOOKUP(Input!$B$13,Library!$A$15:$F$19,4,FALSE),0)+(IFERROR(VLOOKUP(Input!$B$12,Library!$H$15:$K$20,4,FALSE),0))*B10*IFERROR(VLOOKUP(Input!$B$13,Library!$A$15:$F$19,5,FALSE),0))/A10,0),0) | D10: =IFERROR(BOM!$F$17-BOM!$F$16+C10,"") | E10: =IFERROR(IF(CustomerQuote!$B$12="","",IF(Input!$B$17="RMB",MAX((((SUM(BOM!$F$5:$F$6)+SUM(BOM!$F$12:$F$15))/(1-Input!$B$22))+(SUM(BOM!$F$7:$F$11)/(1-Input!$B$28))+C10)/(1-(Input!$B$24+Input!$B$25+Input!$B$26)),D10/(1-Input!$B$23)/(1-(Input!$B$24+Input!$B$25+Input!$B$26))),MAX((((SUM(BOM!$F$5:$F$6)+SUM(BOM!$F$12:$F$15))/(1-Input!$B$22))+(SUM(BOM!$F$7:$F$11)/(1-Input!$B$28))+C10)/(1-(Input!$B$24+Input!$B$25+Input!$B$26)),D10/(1-Input!$B$23)/(1-(Input!$B$24+Input!$B$25+Input!$B$26)))/Input!$B$18)),"") | F10: =IFERROR(E10*A10,"") | G10: =IFERROR(Input!$B$13&" "&IF(OR(Input!$B$13="CFR",Input!$B$13="CIF"),Input!$B$16,Input!$B$15)&", "&Input!$B$14,"")

Sheet CustomerQuote
A1: Customer Quotation
A2: Customer-facing quotation. Internal costs, margins, suppliers and risk reserves are not shown.
A3: Use this sheet for print/PDF export after all required inputs are complete.
A5: Quote No. | B5: =Input!$B$5 | C5: Date | D5: =IF(Input!$B$4="","",Input!$B$4) | E5: Valid Days | F5: =Input!$B$19
A6: Customer | B6: =IF(Input!$B$6="","",Input!$B$6) | C6: Project | D6: =IF(Input!$B$7="","",Input!$B$7) | E6: Sales | F6: =IF(Input!$B$8="","",Input!$B$8)
A7: Product | B7: =IFERROR(IF(Input!$B$9="分体马桶","Two-piece Toilet",IF(Input!$B$9="连体马桶","One-piece Toilet",IF(Input!$B$9="挂墙马桶","Wall-hung Toilet",IF(Input!$B$9="台上盆","Vessel Basin",IF(Input!$B$9="台下盆","Undermount Basin",IF(Input!$B$9="立柱盆/半柱盆","Pedestal / Semi-pedestal Basin",IF(Input!$B$9="","",Input!$B$9))))))),"") | C7: Model | D7: =IF(Input!$B$10="","",Input!$B$10) | E7: Quantity | F7: =IF(Input!$B$11="","",Input!$B$11)
A8: Trade Term | B8: =IF(Input!$B$13="","",Input!$B$13&" "&IF(OR(Input!$B$13="CFR",Input!$B$13="CIF"),Input!$B$16,Input!$B$15)) | C8: Incoterms | D8: =IF(Input!$B$14="","",Input!$B$14) | E8: Currency | F8: =IF(Input!$B$17="","",Input!$B$17)
A9: Port of Loading | B9: =IF(Input!$B$15="","",Input!$B$15) | C9: Destination Port | D9: =IF(Input!$B$16="","",Input!$B$16) | E9: Market | F9: =IFERROR(IF(Input!$B$12="美国","USA",IF(Input!$B$12="欧洲","Europe",IF(Input!$B$12="中东","Middle East",IF(Input!$B$12="亚洲","Asia",IF(Input!$B$12="其他","Other",IF(Input!$B$12="","",Input!$B$12)))))),"")
A10: MOQ | B10: =IF(Input!$B$20="","",Input!$B$20) | C10: Lead Time | D10: =IF(Input!$B$21="","",Input!$B$21&" days") | E10: Payment | F10: T/T 30% deposit, balance before shipment.
A11: Certification | B11: =IF(Input!$E$30="","",IF(Input!$E$30="无","None",Input!$E$30)) | C11: Packing | D11: Standard export carton | E11: Remark | F11: =IF(Input!$E$31="","",Input!$E$31)
A12: Unit Price | B12: =IF(Input!$I$16="待填写","",IF(BOM!$F$19=0,"",BOM!$F$19)) | C12: Total Amount | D12: =IF(OR(Input!$I$16="待填写",BOM!$F$19=0,Input!$B$11=""),"",BOM!$F$19*Input!$B$11) | E12: Price Basis | F12: =IF(OR(Input!$B$13="",Input!$B$14=""),"",Input!$B$13&" "&IF(OR(Input!$B$13="CFR",Input!$B$13="CIF"),Input!$B$16,Input!$B$15)&", "&Input!$B$14)
A13: Seat Cover / Accessory | B13: =IFERROR(IF(Input!$E$9="是",IF(Input!$E$11="PP 普通","PP Standard",IF(Input!$E$11="PP 缓降","PP Soft-close",IF(Input!$E$11="UF 缓降","UF Soft-close",IF(Input!$E$11="UF 快拆","UF Quick-release",IF(Input!$E$11="薄盖快拆","Slim Quick-release",IF(Input!$E$11="智能盖板","Smart Seat Cover",IF(Input!$E$11="","",Input!$E$11))))))),"Not included"),"") | C13: Seat Model | D13: =IF(Input!$E$9="是",Input!$E$10,IF(Input!$E$9="","","-")) | E13: Hinge | F13: =IFERROR(IF(Input!$E$9="是",IF(Input!$E$12="常规","Standard",IF(Input!$E$12="常规缓降","Standard Soft-close",IF(Input!$E$12="快拆缓降","Quick-release Soft-close",IF(Input!$E$12="不锈钢铰链","Stainless Steel Hinge",IF(Input!$E$12="锌合金铰链","Zinc Alloy Hinge",IF(Input!$E$12="金属铰链","Metal Hinge",IF(Input!$E$12="","",Input!$E$12))))))),""),"")
A15: Quantity Price Tiers
A16: Quantity | B16: Unit Price | C16: Total Amount | D16: Trade Term | E16: Lead Time | F16: MOQ | G16: Remark
A17: =IFERROR(Tiers!A7,"") | B17: =IF(Tiers!E7=0,"",Tiers!E7) | C17: =IF(Tiers!F7=0,"",Tiers!F7) | D17: =IF(Input!$B$13="","",Input!$B$13&" "&IF(OR(Input!$B$13="CFR",Input!$B$13="CIF"),Input!$B$16,Input!$B$15)) | E17: =IF(Input!$B$21="","",Input!$B$21&" days") | F17: =IF(Input!$B$20="","",Input!$B$20) | G17: =IF(Input!$B$14="","",Input!$B$14)
A18: =IFERROR(Tiers!A8,"") | B18: =IF(Tiers!E8=0,"",Tiers!E8) | C18: =IF(Tiers!F8=0,"",Tiers!F8) | D18: =IF(Input!$B$13="","",Input!$B$13&" "&IF(OR(Input!$B$13="CFR",Input!$B$13="CIF"),Input!$B$16,Input!$B$15)) | E18: =IF(Input!$B$21="","",Input!$B$21&" days") | F18: =IF(Input!$B$20="","",Input!$B$20) | G18: =IF(Input!$B$14="","",Input!$B$14)
A19: =IFERROR(Tiers!A9,"") | B19: =IF(Tiers!E9=0,"",Tiers!E9) | C19: =IF(Tiers!F9=0,"",Tiers!F9) | D19: =IF(Input!$B$13="","",Input!$B$13&" "&IF(OR(Input!$B$13="CFR",Input!$B$13="CIF"),Input!$B$16,Input!$B$15)) | E19: =IF(Input!$B$21="","",Input!$B$21&" days") | F19: =IF(Input!$B$20="","",Input!$B$20) | G19: =IF(Input!$B$14="","",Input!$B$14)
A20: =IFERROR(Tiers!A10,"") | B20: =IF(Tiers!E10=0,"",Tiers!E10) | C20: =IF(Tiers!F10=0,"",Tiers!F10) | D20: =IF(Input!$B$13="","",Input!$B$13&" "&IF(OR(Input!$B$13="CFR",Input!$B$13="CIF"),Input!$B$16,Input!$B$15)) | E20: =IF(Input!$B$21="","",Input!$B$21&" days") | F20: =IF(Input!$B$20="","",Input!$B$20) | G20: =IF(Input!$B$14="","",Input!$B$14)
A23: Terms
A24: 1. Prices are valid within quotation validity and subject to final order confirmation. DDP requires a separate landed-cost quotation.
A25: 2. Customer version only shows sales prices and trade terms. Internal costs are excluded.
A26: 3. Payment and delivery terms can be adjusted in this sheet before printing if needed.
A27: 4. Please confirm artwork, certification and packing requirements before mass production.

Sheet InternalCost
A1: 内部核价表
A2: 内部查看页：本体成本可直接填；包装、人工、损耗、间接费、物流可自动计算或手动覆盖。客户版不显示这些内部口径。
A3: 核心价格治理 | F3: 关键配件价格
A4: 报价基准成本 RMB/件 | B4: =IFERROR(BOM!$F$17,"") | C4: 报价币种成本/件 | D4: =IFERROR(BOM!$F$18,"") | F4: 项目 | G4: 系统参考 | H4: 最终/型号
A5: 报价币种正式报价/件 | B5: =IFERROR(BOM!$F$19,"") | C5: 订单总额 USD | D5: =IFERROR(BOM!$F$19*Input!$B$11,"") | F5: 盖板档次 | G5: =IFERROR(Input!F11,"") | H5: =IFERROR(Input!E11,"")
A6: 当前净毛利率 | B6: =IFERROR(BOM!$F$22,"") | C6: 销售额预留合计 | D6: =IFERROR(Input!$B$24+Input!$B$25+Input!$B$26,"") | F6: 盖板型号/备注 | G6: =IFERROR(Input!F10,"") | H6: =IFERROR(Input!E10,"")
A7: 自产目标毛利率 | B7: =IFERROR(Input!$B$22,"") | C7: 外购目标毛利率 | D7: =IFERROR(Input!$B$28,"") | F7: 盖板FOB进仓价 | G7: =IFERROR(Input!F11,"") | H7: =IFERROR(IF(Input!G11="",Input!F11,Input!G11),"")
A8: 审批状态 | B8: =IF(OR(Input!$B$6="",Input!$B$7="",Input!$B$9="",Input!$B$10="",Input!$B$11="",Input!$B$12="",Input!$B$13="",Input!$B$15="",Input!$B$16="",Input!$B$17="",Input!$B$18="",Input!$B$20="",Input!$B$21="",Input!$B$22="",Input!$B$23="",Input!$B$24="",Input!$B$25="",Input!$B$26="",Input!$B$27="",Input!$B$28="",Input!$E$29="",Input!$E$30="",N(Input!$B$11)<=0,N(Input!$B$18)<=0,N(Input!$B$20)<=0,N(Input!$B$21)<=0,Input!$B$13="DDP",IF(Input!$G$44="是",OR(N(Input!$E$45)<=0,AND(N(Input!$G$45)<=0,OR(Input!$E$22="",Input!$E$23="",Input!$E$24="",Input!$E$25="",Input!$E$26="",N(Input!$E$22)<=0,N(Input!$E$23)<=0,N(Input!$E$24)<=0,N(Input!$E$25)<=0,N(Input!$E$26)<=0))),OR(Input!$E$22="",Input!$E$23="",Input!$E$24="",Input!$E$25="",Input!$E$26="",N(Input!$E$22)<=0,N(Input!$E$23)<=0,N(Input!$E$24)<=0,N(Input!$E$25)<=0,N(Input!$E$26)<=0)),AND(OR(Input!$B$9="分体马桶",Input!$B$9="连体马桶",Input!$B$9="挂墙马桶"),Input!$E$9=""),AND(OR(Input!$B$9="分体马桶",Input!$B$9="连体马桶",Input!$B$9="挂墙马桶"),Input!$G$44<>"是",Input!$E$9="是",OR(Input!$E$11="",Input!$E$12="")),AND(OR(Input!$B$9="台上盆",Input!$B$9="台下盆",Input!$B$9="立柱盆/半柱盆"),Input!$E$19="")),"待填写",IF(B5<D11,"需特批",IF(B5<B11,"需审批","可提交"))) | C8: 底线净毛利率 | D8: =IFERROR(Input!$B$23,"") | F8: 铰链要求 | G8: =IFERROR(Input!F12,"") | H8: =IFERROR(Input!E12,"")
A9: 条款物流 RMB/件 | B9: =IFERROR(BOM!$F$16,"") | C9: 柜数 | D9: =IFERROR(Tiers!$D$3,"") | F9: 铰链FOB进仓加价 | G9: =IFERROR(Input!F12,"") | H9: =IFERROR(IF(Input!G12="",Input!F12,Input!G12),"")
A10: 装柜量 | B10: =IFERROR(Tiers!$B$3,"") | C10: 汇率 | D10: =IFERROR(Input!$B$18,"") | F10: 盖板计价单价 | G10: =IFERROR(Input!F13,"") | H10: =IFERROR(Input!G13,"")
A11: 审批价/报价币种 | B11: =IFERROR(IF(BOM!$F$19=0,"",IF(Input!$B$17="RMB",BOM!$F$17/(1-Input!$B$23-0.03)/(1-(Input!$B$24+Input!$B$25+Input!$B$26)),BOM!$F$17/(1-Input!$B$23-0.03)/(1-(Input!$B$24+Input!$B$25+Input!$B$26))/Input!$B$18)),"") | C11: 底线价/报价币种 | D11: =IFERROR(IF(BOM!$F$19=0,"",IF(Input!$B$17="RMB",BOM!$F$17/(1-Input!$B$23)/(1-(Input!$B$24+Input!$B$25+Input!$B$26)),BOM!$F$17/(1-Input!$B$23)/(1-(Input!$B$24+Input!$B$25+Input!$B$26))/Input!$B$18)),"") | F11: 水件/五金FOB进仓价 | G11: =IFERROR(Input!F14,"") | H11: =IFERROR(Input!G15,"")
A12: 佣金 RMB/件 | B12: =IFERROR(BOM!$F$20*Input!$B$24,"") | C12: 售后 RMB/件 | D12: =IFERROR(BOM!$F$20*Input!$B$25,"") | F12: 下水/安装件FOB进仓价 | G12: =IFERROR(Input!F20,"") | H12: =IFERROR(Input!G21,"")
A13: 汇率风险 RMB/件 | B13: =IFERROR(BOM!$F$20*Input!$B$26,"") | C13: 目标净毛利 RMB/件 | D13: =IFERROR(BOM!$F$21,"") | F13: 盖板外箱尺寸 | G13: =Input!G34 | H13: =Packing!$B$68
A14: 客户 | B14: =IFERROR(Input!$B$6,"") | C14: 型号 | D14: =IFERROR(Input!$B$10,"") | F14: 盖板装柜量 | G14: =Packing!$B$64 | H14: =Packing!$B$65
A15: 品类 | B15: =IFERROR(Input!$B$9,"") | C15: 数量 | D15: =IFERROR(Input!$B$11,"") | F15: 盖板参考物流 | G15: =Packing!$B$66 | H15: =Packing!$B$66
A16: 备注 | B16: 低于底线价需特批；低于审批价建议常规审批；DDP须专案核价。 | F16: 盖板物流报价处理 | G16: =Input!$E$34 | H16: 不计入报价（FOB进仓价已含）
A17: 包装尺寸 | B17: =IFERROR(TEXT(Packing!$B$18,"0")&" x "&TEXT(Packing!$B$19,"0")&" x "&TEXT(Packing!$B$20,"0")&" mm","") | C17: 装柜限制 | D17: =IFERROR(Packing!$B$37,"")
A18: 自产/本体成本/件 | B18: =IFERROR(SUM(BOM!$F$5:$F$6)+SUM(BOM!$F$12:$F$15),"") | C18: 自产毛利率 | D18: =IFERROR(Input!$B$22,"") | E18: 外购成本/件 | F18: =IFERROR(SUM(BOM!$F$7:$F$11),"") | G18: 外购毛利率 | H18: =IFERROR(Input!$B$28,"")
A19: 成本拆分
A20: 成本层级 | B20: 项目 | C20: 单位 | D20: 数量/件 | E20: 单价/参数 | F20: RMB/件 | G20: 订单总额 RMB | H20: 备注
A21: =IFERROR(BOM!A5,"") | B21: =IFERROR(BOM!B5,"") | C21: =IFERROR(BOM!C5,"") | D21: =IFERROR(BOM!D5,"") | E21: =IFERROR(BOM!E5,"") | F21: =IFERROR(BOM!F5,"") | G21: =IFERROR(BOM!G5,"") | H21: =IFERROR(BOM!H5,"")
A22: =IFERROR(BOM!A6,"") | B22: =IFERROR(BOM!B6,"") | C22: =IFERROR(BOM!C6,"") | D22: =IFERROR(BOM!D6,"") | E22: =IFERROR(BOM!E6,"") | F22: =IFERROR(BOM!F6,"") | G22: =IFERROR(BOM!G6,"") | H22: =IFERROR(BOM!H6,"")
A23: =IFERROR(BOM!A7,"") | B23: =IFERROR(BOM!B7,"") | C23: =IFERROR(BOM!C7,"") | D23: =IFERROR(BOM!D7,"") | E23: =IFERROR(BOM!E7,"") | F23: =IFERROR(BOM!F7,"") | G23: =IFERROR(BOM!G7,"") | H23: =IFERROR(BOM!H7,"")
A24: =IFERROR(BOM!A8,"") | B24: =IFERROR(BOM!B8,"") | C24: =IFERROR(BOM!C8,"") | D24: =IFERROR(BOM!D8,"") | E24: =IFERROR(BOM!E8,"") | F24: =IFERROR(BOM!F8,"") | G24: =IFERROR(BOM!G8,"") | H24: =IFERROR(BOM!H8,"")
A25: =IFERROR(BOM!A9,"") | B25: =IFERROR(BOM!B9,"") | C25: =IFERROR(BOM!C9,"") | D25: =IFERROR(BOM!D9,"") | E25: =IFERROR(BOM!E9,"") | F25: =IFERROR(BOM!F9,"") | G25: =IFERROR(BOM!G9,"") | H25: =IFERROR(BOM!H9,"")
A26: =IFERROR(BOM!A10,"") | B26: =IFERROR(BOM!B10,"") | C26: =IFERROR(BOM!C10,"") | D26: =IFERROR(BOM!D10,"") | E26: =IFERROR(BOM!E10,"") | F26: =IFERROR(BOM!F10,"") | G26: =IFERROR(BOM!G10,"") | H26: =IFERROR(BOM!H10,"")
A27: =IFERROR(BOM!A11,"") | B27: =IFERROR(BOM!B11,"") | C27: =IFERROR(BOM!C11,"") | D27: =IFERROR(BOM!D11,"") | E27: =IFERROR(BOM!E11,"") | F27: =IFERROR(BOM!F11,"") | G27: =IFERROR(BOM!G11,"") | H27: =IFERROR(BOM!H11,"")
A28: =IFERROR(BOM!A12,"") | B28: =IFERROR(BOM!B12,"") | C28: =IFERROR(BOM!C12,"") | D28: =IFERROR(BOM!D12,"") | E28: =IFERROR(BOM!E12,"") | F28: =IFERROR(BOM!F12,"") | G28: =IFERROR(BOM!G12,"") | H28: =IFERROR(BOM!H12,"")
A29: =IFERROR(BOM!A13,"") | B29: =IFERROR(BOM!B13,"") | C29: =IFERROR(BOM!C13,"") | D29: =IFERROR(BOM!D13,"") | E29: =IFERROR(BOM!E13,"") | F29: =IFERROR(BOM!F13,"") | G29: =IFERROR(BOM!G13,"") | H29: =IFERROR(BOM!H13,"")
A30: =IFERROR(BOM!A14,"") | B30: =IFERROR(BOM!B14,"") | C30: =IFERROR(BOM!C14,"") | D30: =IFERROR(BOM!D14,"") | E30: =IFERROR(BOM!E14,"") | F30: =IFERROR(BOM!F14,"") | G30: =IFERROR(BOM!G14,"") | H30: =IFERROR(BOM!H14,"")
A31: =IFERROR(BOM!A15,"") | B31: =IFERROR(BOM!B15,"") | C31: =IFERROR(BOM!C15,"") | D31: =IFERROR(BOM!D15,"") | E31: =IFERROR(BOM!E15,"") | F31: =IFERROR(BOM!F15,"") | G31: =IFERROR(BOM!G15,"") | H31: =IFERROR(BOM!H15,"")
A32: =IFERROR(BOM!A16,"") | B32: =IFERROR(BOM!B16,"") | C32: =IFERROR(BOM!C16,"") | D32: =IFERROR(BOM!D16,"") | E32: =IFERROR(BOM!E16,"") | F32: =IFERROR(BOM!F16,"") | G32: =IFERROR(BOM!G16,"") | H32: =IFERROR(BOM!H16,"")
... A38: =IFERROR(BOM!A22,"") | B38: =IFERROR(BOM!B22,"") | C38: =IFERROR(BOM!C22,"") | D38: =IFERROR(BOM!D22,"") | E38: =IFERROR(BOM!E22,"") | F38: =IFERROR(BOM!F22,"") | G38: =IFERROR(BOM!G22,"") | H38: =IFERROR(BOM!H22,"")
A41: 数量阶梯
A42: =IFERROR(Tiers!A6,"") | B42: =IFERROR(Tiers!B6,"") | C42: =IFERROR(Tiers!C6,"") | D42: =IFERROR(Tiers!D6,"") | E42: =IFERROR(Tiers!E6,"") | F42: =IFERROR(Tiers!F6,"") | G42: =IFERROR(Tiers!G6,"")
A43: =IFERROR(Tiers!A7,"") | B43: =IFERROR(Tiers!B7,"") | C43: =IFERROR(Tiers!C7,"") | D43: =IFERROR(Tiers!D7,"") | E43: =IFERROR(Tiers!E7,"") | F43: =IFERROR(Tiers!F7,"") | G43: =IFERROR(Tiers!G7,"")
A44: =IFERROR(Tiers!A8,"") | B44: =IFERROR(Tiers!B8,"") | C44: =IFERROR(Tiers!C8,"") | D44: =IFERROR(Tiers!D8,"") | E44: =IFERROR(Tiers!E8,"") | F44: =IFERROR(Tiers!F8,"") | G44: =IFERROR(Tiers!G8,"")
A45: =IFERROR(Tiers!A9,"") | B45: =IFERROR(Tiers!B9,"") | C45: =IFERROR(Tiers!C9,"") | D45: =IFERROR(Tiers!D9,"") | E45: =IFERROR(Tiers!E9,"") | F45: =IFERROR(Tiers!F9,"") | G45: =IFERROR(Tiers!G9,"")
A46: =IFERROR(Tiers!A10,"") | B46: =IFERROR(Tiers!B10,"") | C46: =IFERROR(Tiers!C10,"") | D46: =IFERROR(Tiers!D10,"") | E46: =IFERROR(Tiers!E10,"") | F46: =IFERROR(Tiers!F10,"") | G46: =IFERROR(Tiers!G10,"")

Sheet LegacyQuote
A1: 旧版过渡报价表 / Legacy Cost Model - 新版逻辑同步
A2: 旧版同事可继续使用：J列为新版模型自动结果；K-O黄色区域可手填旧表多版本成本；P/Q黄色单元格可改毛利率；橙色提示为草算风险。
A3: Customer / Project 客户/项目 | B3: =IFERROR(Input!$B$6&IF(Input!$B$7="",""," / "&Input!$B$7),"") | D3: Photo: | E3: 产品图片粘贴区 Paste photo here | K3: 报价状态 | L3: =Input!$I$16 | M3: 客户 | N3: =IFERROR(Input!$B$6,"") | P3: 报价币种 | Q3: =IFERROR(Input!$B$17,"") | R3: 汇率 | S3: =IFERROR(Input!$B$18,"")
A4: Factory SKU# 工厂款号 | B4: =IFERROR(Input!$B$10,"") | K4: 订单数量 | L4: =IFERROR(Input!$B$11,"") | M4: MOQ | N4: =IFERROR(Input!$B$20,"") | P4: 报价/件 | Q4: =IF(CustomerQuote!$B$12="","",BOM!$F$19) | R4: 订单总额 | S4: =IF(CustomerQuote!$B$12="","",BOM!$F$19*Input!$B$11)
A5: Description 品名 | B5: =IFERROR(Input!$B$9&IF(Input!$E$9="是"," / "&Input!$E$11&" / "&Input!$E$10,"")&IF(AND(Input!$E$19="是",OR(Input!$B$9="台上盆",Input!$B$9="台下盆",Input!$B$9="立柱盆/半柱盆"))," / 含下水安装件",""),"") | K5: 装柜量 | L5: =IF(CustomerQuote!$B$12="","",Input!$I$11) | M5: 柜数 | N5: =IF(CustomerQuote!$B$12="","",Input!$I$12) | P5: 底线价 | Q5: =IF(CustomerQuote!$B$12="","",Input!$I$9) | R5: 审批价 | S5: =IF(CustomerQuote!$B$12="","",Input!$I$10)
A6: Incoterm 报价方式 | B6: =IFERROR(Input!$B$13&" "&IF(OR(Input!$B$13="CFR",Input!$B$13="CIF"),Input!$B$16,Input!$B$15),"") | K6: 包装尺寸 | L6: =IF(CustomerQuote!$B$12="","",Input!$G$27) | M6: 装柜测算 | N6: =IF(CustomerQuote!$B$12="","",Input!$G$28) | P6: 贸易口径 | Q6: =IFERROR(Input!$B$14,"") | R6: 有效期 | S6: =IFERROR(Input!$B$19&" days","")
A7: Date 核价日期 | B7: =IF(Input!$B$4="","",Input!$B$4) | K7: 重量 | L7: =IFERROR(Input!$E$25&" kg","") | M7: 当前毛利率 | N7: =IF(CustomerQuote!$B$12="","",Input!$I$8) | P7: Margin 1 | Q7: Margin 2 | R7: 盖板参考物流 | S7: =IFERROR(IF(Packing!$B$66=0,"不计入",Packing!$B$66),"")
P8: =IFERROR(Input!$B$22,"") | Q8: =IFERROR(Input!$B$23,"") | R8: 草算提示 | S8: =IF(Input!$B$13="DDP","DDP需专案核价，禁止自动外发",IF(Input!$I$16="待填写","资料未完整，K-O仅供内部草算，禁止外发",IFERROR(Packing!$B$68,"")))
A9: Key Categories 成本类别 | B9: Key Inputs / Material 项目 | C9: GD code 内部编号 | D9: Vendor name 供应商名字 | E9: Vendor product code 供应商产品编号 | F9: Key spec 主要规格 | G9: Unit 数量单位 | H9: Qty 数量 | I9: unit price 单价 | J9: 新版自动 RMB/件 | K9: v1 手动成本 | L9: v2 手动成本 | M9: V3 手动成本 | N9: V4 手动成本 | O9: V5 手动成本 | P9: Margin 1 售价 | Q9: Margin 2 售价 | R9: 旧表备注 | S9: 新版来源/说明
A10: VC cost陶瓷成本 | B10: Tank/cistern lid 水箱盖 | G10: =IF(J10=0,"",IF(OR(10=16,10=17,10=21),"套",IF(OR(10=30,10=31),"率","件"))) | H10: =IF(J10=0,"",1) | I10: =IFERROR(IF(H10="","",J10/H10),"") | J10: =IFERROR(IF(Input!$B$9="分体马桶",(BOM!$F$5+BOM!$F$6)*0.15,0),0) | K10: =IFERROR(J10,"") | L10: =IFERROR(J10,"") | M10: =IFERROR(J10,"") | N10: =IFERROR(J10,"") | O10: =IFERROR(J10,"") | S10: 分体马桶按水箱盖/水箱/座便器拆分；连体按水箱/座便器拆分。
B11: Tank/cistern 水箱 | G11: =IF(J11=0,"",IF(OR(11=16,11=17,11=21),"套",IF(OR(11=30,11=31),"率","件"))) | H11: =IF(J11=0,"",1) | I11: =IFERROR(IF(H11="","",J11/H11),"") | J11: =IFERROR(IF(Input!$B$9="分体马桶",(BOM!$F$5+BOM!$F$6)*0.35,IF(Input!$B$9="连体马桶",(BOM!$F$5+BOM!$F$6)*0.35,0)),0) | K11: =IFERROR(J11,"") | L11: =IFERROR(J11,"") | M11: =IFERROR(J11,"") | N11: =IFERROR(J11,"") | O11: =IFERROR(J11,"") | S11: 旧版展示拆分，不改变新版 BOM 总成本。
B12: toilet bowl/pan 马桶 | G12: =IF(J12=0,"",IF(OR(12=16,12=17,12=21),"套",IF(OR(12=30,12=31),"率","件"))) | H12: =IF(J12=0,"",1) | I12: =IFERROR(IF(H12="","",J12/H12),"") | J12: =IFERROR(IF(OR(Input!$B$9="分体马桶",Input!$B$9="连体马桶",Input!$B$9="挂墙马桶"),(BOM!$F$5+BOM!$F$6)-J10-J11,0),0) | K12: =IFERROR(J12,"") | L12: =IFERROR(J12,"") | M12: =IFERROR(J12,"") | N12: =IFERROR(J12,"") | O12: =IFERROR(J12,"") | S12: K列默认复制J列作为v1。
B13: basin/sink 盆 | G13: =IF(J13=0,"",IF(OR(13=16,13=17,13=21),"套",IF(OR(13=30,13=31),"率","件"))) | H13: =IF(J13=0,"",1) | I13: =IFERROR(IF(H13="","",J13/H13),"") | J13: =IFERROR(IF(OR(Input!$B$9="台上盆",Input!$B$9="台下盆"),BOM!$F$5+BOM!$F$6,IF(Input!$B$9="立柱盆/半柱盆",(BOM!$F$5+BOM!$F$6)*0.65,0)),0) | K13: =IFERROR(J13,"") | L13: =IFERROR(J13,"") | M13: =IFERROR(J13,"") | N13: =IFERROR(J13,"") | O13: =IFERROR(J13,"") | S13: L-O可手动填旧表多版本价，不影响Input/BOM。
B14: Pedestal 立柱 | G14: =IF(J14=0,"",IF(OR(14=16,14=17,14=21),"套",IF(OR(14=30,14=31),"率","件"))) | H14: =IF(J14=0,"",1) | I14: =IFERROR(IF(H14="","",J14/H14),"") | J14: =IFERROR(IF(Input!$B$9="立柱盆/半柱盆",(BOM!$F$5+BOM!$F$6)*0.35,0),0) | K14: =IFERROR(J14,"") | L14: =IFERROR(J14,"") | M14: =IFERROR(J14,"") | N14: =IFERROR(J14,"") | O14: =IFERROR(J14,"") | S14: P/Q按Margin 1/2给出销售价参考。
B15: Small order/MOQ surcharge 小单附加 | G15: =IF(J15=0,"",IF(OR(15=16,15=17,15=21),"套",IF(OR(15=30,15=31),"率","件"))) | H15: =IF(J15=0,"",1) | I15: =IFERROR(IF(H15="","",J15/H15),"") | J15: =IFERROR(BOM!$F$14,0) | K15: =IFERROR(J15,"") | L15: =IFERROR(J15,"") | M15: =IFERROR(J15,"") | N15: =IFERROR(J15,"") | O15: =IFERROR(J15,"") | S15: 低于 MOQ 时的小单摊销。
A16: Accessories 配件 | B16: Flush valve 水件 | G16: =IF(J16=0,"",IF(OR(16=16,16=17,16=21),"套",IF(OR(16=30,16=31),"率","件"))) | H16: =IF(J16=0,"",1) | I16: =IFERROR(IF(H16="","",J16/H16),"") | J16: =IFERROR(BOM!$F$7,0) | K16: =IFERROR(J16,"") | L16: =IFERROR(J16,"") | M16: =IFERROR(J16,"") | N16: =IFERROR(J16,"") | O16: =IFERROR(J16,"") | S16: 内部审批建议使用InternalCost。
B17: Toilet seat 盖板 | C17: 待确认 | E17: =IFERROR(Input!$E$10,"") | F17: =IFERROR(IF(Input!$E$9="是",Input!$E$11&" / "&Input!$E$12,""),"") | G17: =IF(J17=0,"",IF(OR(17=16,17=17,17=21),"套",IF(OR(17=30,17=31),"率","件"))) | H17: =IF(J17=0,"",1) | I17: =IFERROR(IF(H17="","",J17/H17),"") | J17: =IFERROR(BOM!$F$8,0) | K17: =IFERROR(J17,"") | L17: =IFERROR(J17,"") | M17: =IFERROR(J17,"") | N17: =IFERROR(J17,"") | O17: =IFERROR(J17,"") | S17: 读取盖板型号、规格和最终单价
B18: Overflow 溢水环 | G18: =IF(J18=0,"",IF(OR(18=16,18=17,18=21),"套",IF(OR(18=30,18=31),"率","件"))) | H18: =IF(J18=0,"",1) | I18: =IFERROR(IF(H18="","",J18/H18),"") | J18: =0 | K18: =IFERROR(J18,"") | L18: =IFERROR(J18,"") | M18: =IFERROR(J18,"") | N18: =IFERROR(J18,"") | O18: =IFERROR(J18,"") | S18: 溢水件若单独报价，可在 K-O 版本列手动填。
B19: Push button/lever 按键、扳手 | G19: =IF(J19=0,"",IF(OR(19=16,19=17,19=21),"套",IF(OR(19=30,19=31),"率","件"))) | H19: =IF(J19=0,"",1) | I19: =IFERROR(IF(H19="","",J19/H19),"") | J19: =0 | K19: =IFERROR(J19,"") | L19: =IFERROR(J19,"") | M19: =IFERROR(J19,"") | N19: =IFERROR(J19,"") | O19: =IFERROR(J19,"") | S19: 按键/扳手默认含在水件/五金。
B20: Tank fitting kit 水箱安装配件 | G20: =IF(J20=0,"",IF(OR(20=16,20=17,20=21),"套",IF(OR(20=30,20=31),"率","件"))) | H20: =IF(J20=0,"",1) | I20: =IFERROR(IF(H20="","",J20/H20),"") | J20: =0 | K20: =IFERROR(J20,"") | L20: =IFERROR(J20,"") | M20: =IFERROR(J20,"") | N20: =IFERROR(J20,"") | O20: =IFERROR(J20,"") | S20: 水箱安装包默认含在水件/五金。
B21: Toilet fitting kit 安装配件 | G21: =IF(J21=0,"",IF(OR(21=16,21=17,21=21),"套",IF(OR(21=30,21=31),"率","件"))) | H21: =IF(J21=0,"",1) | I21: =IFERROR(IF(H21="","",J21/H21),"") | J21: =IFERROR(BOM!$F$9,0) | K21: =IFERROR(J21,"") | L21: =IFERROR(J21,"") | M21: =IFERROR(J21,"") | N21: =IFERROR(J21,"") | O21: =IFERROR(J21,"") | S21: 台盆下水/安装件在这里过渡显示
B22: Certification/Testing 认证/测试 | G22: =IF(J22=0,"",IF(OR(22=16,22=17,22=21),"套",IF(OR(22=30,22=31),"率","件"))) | H22: =IF(J22=0,"",1) | I22: =IFERROR(IF(H22="","",J22/H22),"") | J22: =IFERROR(BOM!$F$11,0) | K22: =IFERROR(J22,"") | L22: =IFERROR(J22,"") | M22: =IFERROR(J22,"") | N22: =IFERROR(J22,"") | O22: =IFERROR(J22,"") | S22: 认证默认价/覆盖价来自 Input。
A23: Package 包装 | B23: Installation Manual 说明书 | G23: =IF(J23=0,"","本") | H23: 1 | I23: =IFERROR(IF(H23="","",J23/H23),"") | J23: 2 | K23: =IFERROR(J23,"") | L23: =IFERROR(J23,"") | M23: =IFERROR(J23,"") | N23: =IFERROR(J23,"") | O23: =IFERROR(J23,"") | S23: 说明书默认含在包装材料。
B24: Inner pack 内包装 | G24: =IF(J24=0,"","个") | H24: 1 | I24: =IFERROR(IF(H24="","",J24/H24),"") | J24: 6 | K24: =IFERROR(J24,"") | L24: =IFERROR(J24,"") | M24: =IFERROR(J24,"") | N24: =IFERROR(J24,"") | O24: =IFERROR(J24,"") | S24: 内包默认含在包装材料。
B25: outer carton 外箱 | G25: =IF(J25=0,"","个") | H25: 1 | I25: =IFERROR(IF(H25="","",J25/H25),"") | J25: =IFERROR(MAX(BOM!$F$10-J23-J24,0),0) | K25: =IFERROR(J25,"") | L25: =IFERROR(J25,"") | M25: =IFERROR(J25,"") | N25: =IFERROR(J25,"") | O25: =IFERROR(J25,"") | S25: 包装材料自动带入
B26: Pallet 托盘(无特殊要求无) | G26: =IF(J26=0,"",IF(OR(26=16,26=17,26=21),"套",IF(OR(26=30,26=31),"率","件"))) | H26: =IF(J26=0,"",1) | I26: =IFERROR(IF(H26="","",J26/H26),"") | J26: =0 | K26: =IFERROR(J26,"") | L26: =IFERROR(J26,"") | M26: =IFERROR(J26,"") | N26: =IFERROR(J26,"") | O26: =IFERROR(J26,"") | S26: 托盘如客户指定，可在 K-O 版本列手动填。
A27: Labor Cost 人工成本 | B27: Production labor cost 生产人工成本 | G27: =IF(J27=0,"",IF(OR(27=16,27=17,27=21),"套",IF(OR(27=30,27=31),"率","件"))) | H27: =IF(J27=0,"",1) | I27: =IFERROR(IF(H27="","",J27/H27),"") | J27: =IFERROR(BOM!$F$12*0.85,0) | K27: =IFERROR(J27,"") | L27: =IFERROR(J27,"") | M27: =IFERROR(J27,"") | N27: =IFERROR(J27,"") | O27: =IFERROR(J27,"") | S27: 直接人工按生产/包装人工拆分展示。
B28: Packing labor cost 包装人工成本 | G28: =IF(J28=0,"",IF(OR(28=16,28=17,28=21),"套",IF(OR(28=30,28=31),"率","件"))) | H28: =IF(J28=0,"",1) | I28: =IFERROR(IF(H28="","",J28/H28),"") | J28: =IFERROR(BOM!$F$12*0.15,0) | K28: =IFERROR(J28,"") | L28: =IFERROR(J28,"") | M28: =IFERROR(J28,"") | N28: =IFERROR(J28,"") | O28: =IFERROR(J28,"") | S28: 拆分仅用于旧表阅读，合计等于直接人工。
A29: Spoilage 损耗 | B29: Lost for low yield / breakage 损耗预留 | G29: =IF(J29=0,"",IF(OR(29=16,29=17,29=21),"套",IF(OR(29=30,29=31),"率","件"))) | H29: =IF(J29=0,"",1) | I29: =IFERROR(IF(H29="","",J29/H29),"") | J29: =IFERROR(BOM!$F$14,0) | K29: =IFERROR(J29,"") | L29: =IFERROR(J29,"") | M29: =IFERROR(J29,"") | N29: =IFERROR(J29,"") | O29: =IFERROR(J29,"") | S29: 合格率损耗若需单独体现，可在 K-O 手动填。
A30: Indirect Cost 间接费用 | B30: Tooling / manufacturing overhead 制造间接 | G30: =IF(J30=0,"",IF(OR(30=16,30=17,30=21),"套",IF(OR(30=30,30=31),"率","件"))) | H30: =IF(J30=0,"",1) | I30: =IFERROR(IF(H30="","",J30/H30),"") | J30: =IFERROR(BOM!$F$13,0) | K30: =IFERROR(J30,"") | L30: =IFERROR(J30,"") | M30: =IFERROR(J30,"") | N30: =IFERROR(J30,"") | O30: =IFERROR(J30,"") | S30: 制造费用自动带入
B31: Management fee 经营/管理间接费 | G31: =IF(J31=0,"",IF(OR(31=16,31=17,31=21),"套",IF(OR(31=30,31=31),"率","件"))) | H31: =IF(J31=0,"",1) | I31: =IFERROR(IF(H31="","",J31/H31),"") | J31: =IFERROR(BOM!$F$15,0) | K31: =IFERROR(J31,"") | L31: =IFERROR(J31,"") | M31: =IFERROR(J31,"") | N31: =IFERROR(J31,"") | O31: =IFERROR(J31,"") | S31: 经营费用自动带入
A32: Sub Total cost | B32: RMB 产品成本 | J32: =IFERROR(SUM(J10:J31),"") | K32: =IFERROR(SUM(K10:K31),"") | L32: =IFERROR(SUM(L10:L31),"") | M32: =IFERROR(SUM(M10:M31),"") | N32: =IFERROR(SUM(N10:N31),"") | O32: =IFERROR(SUM(O10:O31),"") | S32: 未含条款物流
B33: local charges 物流费用 | G33: 套 | H33: 1 | J33: =IFERROR(BOM!$F$16,0) | K33: =IFERROR(J33,"") | L33: =IFERROR(J33,"") | M33: =IFERROR(J33,"") | N33: =IFERROR(J33,"") | O33: =IFERROR(J33,"") | S33: 条款物流
B34: 人民币总成本 | J34: =IFERROR(BOM!$F$17,"") | K34: =IFERROR(K32+K33,"") | L34: =IFERROR(L32+L33,"") | M34: =IFERROR(M32+M33,"") | N34: =IFERROR(N32+N33,"") | O34: =IFERROR(O32+O33,"") | S34: 产品成本 + 物流
A35: Profit | B35: Profit 利润 | J35: =IFERROR(BOM!$F$21,"") | K35: =IFERROR(IF(K38="","",K38*IF(Input!$B$17="RMB",1,IF(N(Input!$B$18)>0,Input!$B$18,7.2))-K34-K38*IF(Input!$B$17="RMB",1,IF(N(Input!$B$18)>0,Input!$B$18,7.2))*(N(Input!$B$24)+N(Input!$B$25)+N(Input!$B$26))),"") | L35: =IFERROR(IF(L38="","",L38*IF(Input!$B$17="RMB",1,IF(N(Input!$B$18)>0,Input!$B$18,7.2))-L34-L38*IF(Input!$B$17="RMB",1,IF(N(Input!$B$18)>0,Input!$B$18,7.2))*(N(Input!$B$24)+N(Input!$B$25)+N(Input!$B$26))),"") | M35: =IFERROR(IF(M38="","",M38*IF(Input!$B$17="RMB",1,IF(N(Input!$B$18)>0,Input!$B$18,7.2))-M34-M38*IF(Input!$B$17="RMB",1,IF(N(Input!$B$18)>0,Input!$B$18,7.2))*(N(Input!$B$24)+N(Input!$B$25)+N(Input!$B$26))),"") | N35: =IFERROR(IF(N38="","",N38*IF(Input!$B$17="RMB",1,IF(N(Input!$B$18)>0,Input!$B$18,7.2))-N34-N38*IF(Input!$B$17="RMB",1,IF(N(Input!$B$18)>0,Input!$B$18,7.2))*(N(Input!$B$24)+N(Input!$B$25)+N(Input!$B$26))),"") | O35: =IFERROR(IF(O38="","",O38*IF(Input!$B$17="RMB",1,IF(N(Input!$B$18)>0,Input!$B$18,7.2))-O34-O38*IF(Input!$B$17="RMB",1,IF(N(Input!$B$18)>0,Input!$B$18,7.2))*(N(Input!$B$24)+N(Input!$B$25)+N(Input!$B$26))),"") | P35: =IFERROR(P38*IF(Input!$B$17="RMB",1,Input!$B$18)-J34-P38*IF(Input!$B$17="RMB",1,Input!$B$18)*(Input!$B$24+Input!$B$25+Input!$B$26),"") | Q35: =IFERROR(Q38*IF(Input!$B$17="RMB",1,Input!$B$18)-J34-Q38*IF(Input!$B$17="RMB",1,Input!$B$18)*(Input!$B$24+Input!$B$25+Input!$B$26),"") | S35: 目标净毛利
A36: Exchange rate | B36: 报价币种 / 汇率 | J36: =IFERROR(Input!$B$17&" / "&Input!$B$18,"") | K36: =IFERROR(Input!$B$18,"") | L36: =IFERROR(Input!$B$18,"") | M36: =IFERROR(Input!$B$18,"") | N36: =IFERROR(Input!$B$18,"") | O36: =IFERROR(Input!$B$18,"")
A37: Total cost | B37: 报价币种成本 | J37: =IF(CustomerQuote!$B$12="","",BOM!$F$18) | K37: =IFERROR(IF(Input!$B$17="RMB",K34,K34/IF(N(Input!$B$18)>0,Input!$B$18,7.2)),"") | L37: =IFERROR(IF(Input!$B$17="RMB",L34,L34/IF(N(Input!$B$18)>0,Input!$B$18,7.2)),"") | M37: =IFERROR(IF(Input!$B$17="RMB",M34,M34/IF(N(Input!$B$18)>0,Input!$B$18,7.2)),"") | N37: =IFERROR(IF(Input!$B$17="RMB",N34,N34/IF(N(Input!$B$18)>0,Input!$B$18,7.2)),"") | O37: =IFERROR(IF(Input!$B$17="RMB",O34,O34/IF(N(Input!$B$18)>0,Input!$B$18,7.2)),"") | P37: =IFERROR(J37,"") | Q37: =IFERROR(J37,"")
B38: 报价币种销售价 | J38: =IF(CustomerQuote!$B$12="","",BOM!$F$19) | K38: =IFERROR(IF(AND(K37<>"",1-IF(N(Input!$B$22)>0,Input!$B$22,0.18)-(N(Input!$B$24)+N(Input!$B$25)+N(Input!$B$26))>0,1-IF(N(Input!$B$23)>0,Input!$B$23,0.1)-(N(Input!$B$24)+N(Input!$B$25)+N(Input!$B$26))>0),MAX(K37/(1-IF(N(Input!$B$22)>0,Input!$B$22,0.18)-(N(Input!$B$24)+N(Input!$B$25)+N(Input!$B$26))),K37/(1-IF(N(Input!$B$23)>0,Input!$B$23,0.1)-(N(Input!$B$24)+N(Input!$B$25)+N(Input!$B$26)))),""),"") | L38: =IFERROR(IF(AND(L37<>"",1-IF(N(Input!$B$22)>0,Input!$B$22,0.18)-(N(Input!$B$24)+N(Input!$B$25)+N(Input!$B$26))>0,1-IF(N(Input!$B$23)>0,Input!$B$23,0.1)-(N(Input!$B$24)+N(Input!$B$25)+N(Input!$B$26))>0),MAX(L37/(1-IF(N(Input!$B$22)>0,Input!$B$22,0.18)-(N(Input!$B$24)+N(Input!$B$25)+N(Input!$B$26))),L37/(1-IF(N(Input!$B$23)>0,Input!$B$23,0.1)-(N(Input!$B$24)+N(Input!$B$25)+N(Input!$B$26)))),""),"") | M38: =IFERROR(IF(AND(M37<>"",1-IF(N(Input!$B$22)>0,Input!$B$22,0.18)-(N(Input!$B$24)+N(Input!$B$25)+N(Input!$B$26))>0,1-IF(N(Input!$B$23)>0,Input!$B$23,0.1)-(N(Input!$B$24)+N(Input!$B$25)+N(Input!$B$26))>0),MAX(M37/(1-IF(N(Input!$B$22)>0,Input!$B$22,0.18)-(N(Input!$B$24)+N(Input!$B$25)+N(Input!$B$26))),M37/(1-IF(N(Input!$B$23)>0,Input!$B$23,0.1)-(N(Input!$B$24)+N(Input!$B$25)+N(Input!$B$26)))),""),"") | N38: =IFERROR(IF(AND(N37<>"",1-IF(N(Input!$B$22)>0,Input!$B$22,0.18)-(N(Input!$B$24)+N(Input!$B$25)+N(Input!$B$26))>0,1-IF(N(Input!$B$23)>0,Input!$B$23,0.1)-(N(Input!$B$24)+N(Input!$B$25)+N(Input!$B$26))>0),MAX(N37/(1-IF(N(Input!$B$22)>0,Input!$B$22,0.18)-(N(Input!$B$24)+N(Input!$B$25)+N(Input!$B$26))),N37/(1-IF(N(Input!$B$23)>0,Input!$B$23,0.1)-(N(Input!$B$24)+N(Input!$B$25)+N(Input!$B$26)))),""),"") | O38: =IFERROR(IF(AND(O37<>"",1-IF(N(Input!$B$22)>0,Input!$B$22,0.18)-(N(Input!$B$24)+N(Input!$B$25)+N(Input!$B$26))>0,1-IF(N(Input!$B$23)>0,Input!$B$23,0.1)-(N(Input!$B$24)+N(Input!$B$25)+N(Input!$B$26))>0),MAX(O37/(1-IF(N(Input!$B$22)>0,Input!$B$22,0.18)-(N(Input!$B$24)+N(Input!$B$25)+N(Input!$B$26))),O37/(1-IF(N(Input!$B$23)>0,Input!$B$23,0.1)-(N(Input!$B$24)+N(Input!$B$25)+N(Input!$B$26)))),""),"") | P38: =IFERROR(IF(CustomerQuote!$B$12="","",IF(1-$P$8-Input!$B$24-Input!$B$25-Input!$B$26>0,J37/(1-$P$8-Input!$B$24-Input!$B$25-Input!$B$26),0)),"") | Q38: =IFERROR(IF(CustomerQuote!$B$12="","",IF(1-$Q$8-Input!$B$24-Input!$B$25-Input!$B$26>0,J37/(1-$Q$8-Input!$B$24-Input!$B$25-Input!$B$26),0)),"")
A41: 数量阶梯报价 / Quantity Price Tiers | K41: 包装与物流摘要 / Packing & Logistics
A42: Quantity 数量 | B42: Cabinets 柜数 | C42: Logistics RMB/件 | D42: Cost RMB/件 | E42: Unit Price 报价币种/件 | F42: Total Amount 订单总额 | G42: Trade Term 条款 | K42: 外箱尺寸 | L42: =IF(CustomerQuote!$B$12="","",Input!$G$27) | P42: 盖板外箱 | Q42: =IFERROR(Input!$G$34,"")
...

Sheet Packing
A1: 包装与装柜测算
A2: 自动测算页：不要在这里改。回第一个“填写首页”或 Input 黄色格修改尺寸、净重、每箱件数和柜型。
A3: 当前包装结果 | F3: 品类包装规则 | M3: 每箱件数排布表
A4: 项目 | B4: 当前值 | C4: 说明 | F4: 产品品类 | G4: 包装方式 | H4: 外箱外扩/边 | I4: 内包外扩/边 | J4: 纸板密度KG/㎡ | K4: 辅材KG/件 | M4: 每箱件数 | N4: X | O4: Y | P4: Z
A5: 产品品类 | B5: =IFERROR(Input!$B$9,"") | C5: 来自 Input!B9 | F5: 分体马桶 | G5: 单套外箱 | H5: 15 | I5: 5 | J5: 0.82 | K5: 4.2 | M5: 1 | N5: 1 | O5: 1 | P5: 1
A6: 包装方式 | B6: =IFERROR(VLOOKUP($B$5,$F$5:$K$10,2,FALSE),"") | C6: 按品类规则自动带出 | F6: 连体马桶 | G6: 单套外箱 | H6: 15 | I6: 5 | J6: 0.82 | K6: 5.2 | M6: 2 | N6: 1 | O6: 1 | P6: 2
A7: 每箱件数 | B7: =IFERROR(MAX(1,Input!$E$26),"") | C7: 来自 Input!E26，可在 Input 手动调整 | F7: 挂墙马桶 | G7: 单套外箱 | H7: 15 | I7: 5 | J7: 0.82 | K7: 3.6 | M7: 3 | N7: 1 | O7: 1 | P7: 3
A8: 产品长 mm | B8: =IFERROR(Input!$E$22,"") | C8: 产品本体尺寸 | F8: 台上盆 | G8: 单盆外箱 | H8: 14 | I8: 5 | J8: 0.8 | K8: 2.1 | M8: 4 | N8: 2 | O8: 2 | P8: 1
A9: 产品宽 mm | B9: =IFERROR(Input!$E$23,"") | C9: 产品本体尺寸 | F9: 台下盆 | G9: 单盆外箱 | H9: 14 | I9: 5 | J9: 0.8 | K9: 1.8 | M9: 5 | N9: 1 | O9: 1 | P9: 5
A10: 产品高 mm | B10: =IFERROR(Input!$E$24,"") | C10: 产品本体尺寸 | F10: 立柱盆/半柱盆 | G10: 单套外箱 | H10: 15 | I10: 5 | J10: 0.82 | K10: 3.1 | M10: 6 | N10: 1 | O10: 2 | P10: 3
A11: 外箱单边外扩 mm | B11: =IFERROR(VLOOKUP($B$5,$F$5:$K$10,3,FALSE),15) | C11: 参考 HTML 包装外扩规则 | M11: 7 | N11: 1 | O11: 1 | P11: 7
A12: 内包单边外扩 mm | B12: =IFERROR(VLOOKUP($B$5,$F$5:$K$10,4,FALSE),5) | C12: 每件内包缓冲 | M12: 8 | N12: 2 | O12: 2 | P12: 2
A13: 纸板密度 KG/㎡ | B13: =IFERROR(VLOOKUP($B$5,$F$5:$K$10,5,FALSE),0.82) | C13: 用于估算纸箱重量 | F13: 柜型装载参数 | M13: 9 | N13: 1 | O13: 3 | P13: 3
A14: 辅材重量 KG/件 | B14: =IFERROR(VLOOKUP($B$5,$F$5:$K$10,6,FALSE),3) | C14: 泡沫、护角、配件小包等 | F14: 柜型 | G14: 柜内容积CBM | H14: 有效装载CBM | I14: 限重KG | J14: 说明 | M14: 10 | N14: 1 | O14: 2 | P14: 5
A15: 排布 X | B15: =IFERROR(VLOOKUP($B$7,$M$5:$P$18,2,FALSE),1) | C15: 多件/箱时使用 | F15: 40HQ | G15: 66 | H15: 66 | I15: 26500 | J15: 常规高柜，参考 HTML 40HQ 常规装柜 | M15: 11 | N15: 1 | O15: 1 | P15: 11
A16: 排布 Y | B16: =IFERROR(VLOOKUP($B$7,$M$5:$P$18,3,FALSE),1) | C16: 多件/箱时使用 | F16: 40GP | G16: 58 | H16: 56 | I16: 26500 | J16: 普柜，按常用可用体积保守估算 | M16: 12 | N16: 2 | O16: 2 | P16: 3
A17: 排布 Z | B17: =IFERROR(VLOOKUP($B$7,$M$5:$P$18,4,FALSE),$B$7) | C17: 多件/箱时使用 | F17: 20GP | G17: 28 | H17: 25.8 | I17: 21500 | J17: 参考 HTML 20GP 常规装柜 | M17: 24 | N17: 2 | O17: 3 | P17: 4
A18: 外箱长 mm | B18: =IFERROR(IF($B$7>1,($B$8+$B$12*2)*$B$15+$B$11*2,$B$8+$B$11*2),"") | C18: 产品尺寸 + 内包 + 外箱外扩 | M18: 50 | N18: 5 | O18: 5 | P18: 2
A19: 外箱宽 mm | B19: =IFERROR(IF($B$7>1,($B$9+$B$12*2)*$B$16+$B$11*2,$B$9+$B$11*2),"") | C19: 产品尺寸 + 内包 + 外箱外扩
A20: 外箱高 mm | B20: =IFERROR(IF($B$7>1,($B$10+$B$12*2)*$B$17+$B$11*2,$B$10+$B$11*2),"") | C20: 产品尺寸 + 内包 + 外箱外扩
A21: 单箱 CBM | B21: =IFERROR($B$18*$B$19*$B$20/1000000000,0) | C21: 外箱长 × 宽 × 高
A22: 单件摊分 CBM | B22: =IFERROR($B$21/$B$7,0) | C22: 单箱 CBM / 每箱件数
A23: 纸箱展开面积 ㎡ | B23: =IFERROR(IF(AND($B$18>0,$B$19>0,$B$20>0),2*(($B$18/1000)*($B$19/1000)+($B$18/1000)*($B$20/1000)+($B$19/1000)*($B$20/1000)),0),"") | C23: 2 × (LW + LH + WH)
A24: 纸箱重量 KG | B24: =IFERROR($B$23*$B$13,"") | C24: 展开面积 × 纸板密度
A25: 包装增重 KG/箱 | B25: =IFERROR($B$24+$B$14*$B$7,"") | C25: 纸箱重量 + 辅材重量
A26: 单箱净重 KG | B26: =IFERROR(Input!$E$25*$B$7,"") | C26: 净重/件 × 每箱件数
A27: 单箱毛重 KG | B27: =IFERROR($B$26+$B$25,"") | C27: 单箱净重 + 包装增重
A28: 单件摊分毛重 KG | B28: =IFERROR($B$27/$B$7,0) | C28: 单箱毛重 / 每箱件数
A29: 柜型 | B29: =IFERROR(Input!$E$29,"") | C29: 来自 Input!E29
A30: 柜内容积 CBM | B30: =IFERROR(VLOOKUP($B$29,$F$15:$J$17,2,FALSE),66) | C30: 柜型理论容积
A31: 有效装载 CBM | B31: =IFERROR(VLOOKUP($B$29,$F$15:$J$17,3,FALSE),66) | C31: 扣除装柜损耗后的可用体积
A32: 柜限重 KG | B32: =IFERROR(VLOOKUP($B$29,$F$15:$J$17,4,FALSE),26500) | C32: 按货物净载重口径
A33: 按体积可装箱数 | B33: =IFERROR(IF($B$21>0,FLOOR($B$31/$B$21,1),0),"") | C33: 有效装载 CBM / 单箱 CBM
A34: 按重量可装箱数 | B34: =IFERROR(IF($B$27>0,FLOOR($B$32/$B$27,1),0),"") | C34: 柜限重 / 单箱毛重
