Workbook
Name NigeriaCostTerms: Lists!$A$1:$A$4
Name ChinaCostTerms: Lists!$B$1:$B$5
Name ManualCostTerms: Lists!$C$1:$C$1
Name QuoteSources: Lists!$D$1:$D$4
Name SupplyPaths: Lists!$E$1:$E$4
Name CostHandling: Lists!$F$1:$F$4
Name YesNo: Lists!$G$1:$G$2
Name Currencies: Lists!$H$1:$H$2
Name CustomerTerms: Lists!$I$1:$I$5
Name QuoteDisplayModes: Lists!$J$1:$J$2
Name AllocationMethods: Lists!$K$1:$K$4
Name EnableStatus: Lists!$L$1:$L$2
Name LogisticsInputModes: Lists!$M$1:$M$2
Name LogisticsBasisModes: Lists!$N$1:$N$3

Sheet 填写首页
A1: 卫浴陶瓷报价表 - 第一版改造
A2: 销售只录入真实询价结果；表格按价格口径、供应链路径、成本处理方式自动判断BOM、物流、客户展示和风险。
A4: 客户名称 | C4: 项目名称 | E4: 报价单号 | F4: QT-20260529-001 | G4: 报价日期 | H4: =TODAY() | I4: 客户报价币种 | J4: USD | K4: 产品图片 1 粘贴图片到此处 | N4: 产品图片 2 粘贴图片到此处
A5: 型号编号 | B5: GD1A603-EL-S | C5: 订单数量 | D5: 600 | E5: 报价汇率 | F5: 6.6 | G5: 目标成本加价率 | H5: 0.3 | I5: 底线成本加价率 | J5: 0
A6: 客户报价条款 | B6: FOB尼日利亚港 | C6: 目的港 | D6: Lagos-Apapa | E6: 报价显示方式 | F6: 套装总价 | G6: 外购件成本加价率 | H6: 0.03 | I6: 是否DDP/项目例外 | J6: 否
A7: 保险费率 | B7: 0 | C7: 保险金额RMB | D7: 0 | E7: 手动项目报价审批人 | G7: 手动项目报价审批日期 | I7: 手动项目报价有效期
A8: 尼日利亚默认装柜量 | B8: 600 | C8: 中国配件默认装柜量 | D8: 600 | E8: 手动项目报价原因 | G8: 客户备注 | I8: 内部备注
A9: 总成本RMB/件 | B9: =InternalCost!B4+InternalCost!D4+InternalCost!B6+InternalCost!F4 | C9: 目标利润RMB/件 | D9: =InternalCost!F7 | E9: 综合成本加价率 | F9: =InternalCost!B10 | G9: 销售价USD/件 | H9: =InternalCost!F9 | I9: 整单销售额USD | J9: =H9*$D$5
A10: 成本录入区
A12: 类别 | B12: 项目 | C12: 人民币金额 | D12: 报价来源 | E12: 价格口径 | F12: 供应链路径 | G12: 成本处理方式 | H12: 是否参与整体加价复核 | I12: 生效成本RMB | J12: 手动原因 | K12: 审批人 | L12: 审批日期 | M12: 有效期 | N12: 备注 | O12: 物流取数方式 | P12: 物流公式测算RMB
A13: VC cost陶瓷成本 | B13: Tank/cistern lid水箱盖 | D13: 尼日利亚工厂 | E13: 尼厂出厂成本 | F13: 尼日利亚工厂配套后出货 | G13: 计入套装BOM | H13: 是 | I13: =N($C13)
A14: VC cost陶瓷成本 | B14: Tank/cistern 水箱 | D14: 尼日利亚工厂 | E14: 尼厂出厂成本 | F14: 尼日利亚工厂配套后出货 | G14: 计入套装BOM | H14: 是 | I14: =N($C14)
A15: VC cost陶瓷成本 | B15: toilet bowl/pan马桶 | C15: 47.824781 | D15: 尼日利亚工厂 | E15: 尼厂出厂成本 | F15: 尼日利亚工厂配套后出货 | G15: 计入套装BOM | H15: 是 | I15: =N($C15) | N15: 旧表GD1A603-EL-S样例
A16: VC cost陶瓷成本 | B16: basin/sink盆 | D16: 尼日利亚工厂 | E16: 尼厂出厂成本 | F16: 尼日利亚工厂配套后出货 | G16: 仅参考不计入 | H16: 否 | I16: =N($C16)
A17: VC cost陶瓷成本 | B17: Pedestal | D17: 尼日利亚工厂 | E17: 尼厂出厂成本 | F17: 尼日利亚工厂配套后出货 | G17: 仅参考不计入 | H17: 否 | I17: =N($C17)
A18: Accessories 配件 | B18: Flush valve 水件 | D18: 中国供应商 | E18: 送中国指定仓/进仓价 | F18: 中国配件发尼厂后配套 | G18: 计入套装BOM | H18: 是 | I18: =N($C18)
A19: Accessories 配件 | B19: Toilet seat盖板 | D19: 中国供应商 | E19: 送中国指定仓/进仓价 | F19: 中国配件发尼厂后配套 | G19: 计入套装BOM | H19: 是 | I19: =N($C19)
A20: Accessories 配件 | B20: Overflow 溢水环 | D20: 中国供应商 | E20: 送中国指定仓/进仓价 | F20: 中国配件直发客户 | G20: 客户单独报价 | H20: 是 | I20: =N($C20)
A21: Accessories 配件 | B21: Push button/lever按键、扳手 | D21: 中国供应商 | E21: 送中国指定仓/进仓价 | F21: 中国配件发尼厂后配套 | G21: 计入套装BOM | H21: 是 | I21: =N($C21)
A22: Accessories 配件 | B22: Tank fitting kit 水箱安装配件 | D22: 中国供应商 | E22: 送中国指定仓/进仓价 | F22: 中国配件发尼厂后配套 | G22: 计入套装BOM | H22: 是 | I22: =N($C22)
A23: Accessories 配件 | B23: Toilet fitting kit安装配件 | D23: 中国供应商 | E23: 送中国指定仓/进仓价 | F23: 中国配件发尼厂后配套 | G23: 计入套装BOM | H23: 是 | I23: =N($C23)
A24: Accessories 配件 | B24: others 其他配件 | D24: 中国供应商 | E24: 送中国指定仓/进仓价 | F24: 中国配件直发客户 | G24: 客户单独报价 | H24: 是 | I24: =N($C24)
A25: Package 包装 | B25: Installation Manual说明书 | C25: 2 | D25: 中国供应商 | E25: 送中国指定仓/进仓价 | F25: 中国配件发尼厂后配套 | G25: 计入套装BOM | H25: 是 | I25: =N($C25) | N25: 旧表样例
A26: Package 包装 | B26: Inner pack内包装 | C26: 6 | D26: 尼日利亚本地供应商 | E26: 尼厂装柜成本 | F26: 尼日利亚本地采购配套 | G26: 计入套装BOM | H26: 是 | I26: =N($C26) | N26: 旧表样例
A27: Package 包装 | B27: outer carton外箱 | C27: 12.8 | D27: 尼日利亚本地供应商 | E27: 尼厂装柜成本 | F27: 尼日利亚本地采购配套 | G27: 计入套装BOM | H27: 是 | I27: =N($C27) | N27: 旧表样例
A28: Package 包装 | B28: Pallet托盘 | D28: 尼日利亚本地供应商 | E28: 尼厂装柜成本 | F28: 尼日利亚本地采购配套 | G28: 仅参考不计入 | H28: 否 | I28: =N($C28)
A29: Labor Cost 人工成本 | B29: Production labor cost生产人工成本 | C29: 6.2465905 | D29: 尼日利亚工厂 | E29: 尼厂出厂成本 | F29: 尼日利亚工厂配套后出货 | G29: 计入套装BOM | H29: 是 | I29: =N($C29) | N29: 旧表样例
A30: Labor Cost 人工成本 | B30: Packing labor cost 包装人工成本 | C30: 0.97602987 | D30: 尼日利亚工厂 | E30: 尼厂装柜成本 | F30: 尼日利亚工厂配套后出货 | G30: 计入套装BOM | H30: 是 | I30: =N($C30) | N30: 旧表样例
A31: Spoilage 损耗 | B31: Lost for low yield 合格率损耗 | C31: 9.435119 | D31: 尼日利亚工厂 | E31: 手动确认成本 | F31: 尼日利亚工厂配套后出货 | G31: 计入套装BOM | H31: 是 | I31: =N($C31) | N31: 旧表样例
A32: Indirect Cost 间接费用 | B32: Tooling 模具分摊 | C32: 2.554831 | D32: 手动确认 | E32: 手动确认成本 | F32: 尼日利亚工厂配套后出货 | G32: 计入套装BOM | H32: 是 | I32: =N($C32) | N32: 旧表样例
A33: Indirect Cost 间接费用 | B33: Management fee管理/财务/其他 | C33: 7 | D33: 尼日利亚工厂 | E33: 尼厂出厂成本 | F33: 尼日利亚工厂配套后出货 | G33: 计入套装BOM | H33: 是 | I33: =N($C33) | N33: 旧表样例
A34: Logistics 物流 | B34: 物流成本 | D34: 手动确认 | E34: 手动确认成本 | F34: 尼日利亚工厂配套后出货 | G34: 计入套装BOM | H34: 否 | I34: =IF($O34="公式测算",$P34,$C34) | N34: 选择公式测算时自动取计入BOM物流；选择手动填写时使用C列金额。物流不参与成本加价。 | O34: 公式测算 | P34: =物流测算!C6
A37: 产品与包装信息区
A38: 记录产品尺寸、重量、包装尺寸、毛重、每箱件数、CBM和装柜量；计入报价的项目未补齐时，检查页会报警。
A39: 类别 | B39: 项目 | C39: 每套用量 | D39: 产品长mm | E39: 产品宽mm | F39: 产品高mm | G39: 净重KG/件 | H39: 每箱件数 | I39: 包装长mm | J39: 包装宽mm | K39: 包装高mm | L39: 毛重KG/箱 | M39: 整箱CBM | N39: 单件CBM | O39: 单件毛重KG | P39: 体积可装件数 | Q39: 重量可装件数 | R39: 建议装柜量 | S39: 限制因素 | T39: 供应链路径 | U39: 备注
A40: =A13 | B40: =B13 | C40: 1 | M40: =IFERROR(IF(OR(I40="",J40="",K40=""),"",I40*J40*K40/1000000000),"") | N40: =IFERROR(IF(OR(M40="",H40=""),"",M40/MAX(H40,1)),"") | O40: =IFERROR(IF(OR(L40="",H40=""),"",L40/MAX(H40,1)),"") | P40: =IFERROR(IF(N40="","",ROUNDDOWN(装柜测算!$B$4*装柜测算!$B$6/MAX(N40,0.0001),0)),"") | Q40: =IFERROR(IF(O40="","",ROUNDDOWN(MAX(0,装柜测算!$B$5-装柜测算!$B$7)/MAX(O40,0.0001),0)),"") | R40: =IFERROR(IF(OR(P40="",Q40=""),"",MIN(P40,Q40)),"") | S40: =IF(R40="","",IF(P40<Q40,"体积限制",IF(Q40<P40,"重量限制","体积/重量接近"))) | T40: =F13
A41: =A14 | B41: =B14 | C41: 1 | M41: =IFERROR(IF(OR(I41="",J41="",K41=""),"",I41*J41*K41/1000000000),"") | N41: =IFERROR(IF(OR(M41="",H41=""),"",M41/MAX(H41,1)),"") | O41: =IFERROR(IF(OR(L41="",H41=""),"",L41/MAX(H41,1)),"") | P41: =IFERROR(IF(N41="","",ROUNDDOWN(装柜测算!$B$4*装柜测算!$B$6/MAX(N41,0.0001),0)),"") | Q41: =IFERROR(IF(O41="","",ROUNDDOWN(MAX(0,装柜测算!$B$5-装柜测算!$B$7)/MAX(O41,0.0001),0)),"") | R41: =IFERROR(IF(OR(P41="",Q41=""),"",MIN(P41,Q41)),"") | S41: =IF(R41="","",IF(P41<Q41,"体积限制",IF(Q41<P41,"重量限制","体积/重量接近"))) | T41: =F14
A42: =A15 | B42: =B15 | C42: 1 | M42: =IFERROR(IF(OR(I42="",J42="",K42=""),"",I42*J42*K42/1000000000),"") | N42: =IFERROR(IF(OR(M42="",H42=""),"",M42/MAX(H42,1)),"") | O42: =IFERROR(IF(OR(L42="",H42=""),"",L42/MAX(H42,1)),"") | P42: =IFERROR(IF(N42="","",ROUNDDOWN(装柜测算!$B$4*装柜测算!$B$6/MAX(N42,0.0001),0)),"") | Q42: =IFERROR(IF(O42="","",ROUNDDOWN(MAX(0,装柜测算!$B$5-装柜测算!$B$7)/MAX(O42,0.0001),0)),"") | R42: =IFERROR(IF(OR(P42="",Q42=""),"",MIN(P42,Q42)),"") | S42: =IF(R42="","",IF(P42<Q42,"体积限制",IF(Q42<P42,"重量限制","体积/重量接近"))) | T42: =F15
A43: =A16 | B43: =B16 | C43: 1 | M43: =IFERROR(IF(OR(I43="",J43="",K43=""),"",I43*J43*K43/1000000000),"") | N43: =IFERROR(IF(OR(M43="",H43=""),"",M43/MAX(H43,1)),"") | O43: =IFERROR(IF(OR(L43="",H43=""),"",L43/MAX(H43,1)),"") | P43: =IFERROR(IF(N43="","",ROUNDDOWN(装柜测算!$B$4*装柜测算!$B$6/MAX(N43,0.0001),0)),"") | Q43: =IFERROR(IF(O43="","",ROUNDDOWN(MAX(0,装柜测算!$B$5-装柜测算!$B$7)/MAX(O43,0.0001),0)),"") | R43: =IFERROR(IF(OR(P43="",Q43=""),"",MIN(P43,Q43)),"") | S43: =IF(R43="","",IF(P43<Q43,"体积限制",IF(Q43<P43,"重量限制","体积/重量接近"))) | T43: =F16
A44: =A17 | B44: =B17 | C44: 1 | M44: =IFERROR(IF(OR(I44="",J44="",K44=""),"",I44*J44*K44/1000000000),"") | N44: =IFERROR(IF(OR(M44="",H44=""),"",M44/MAX(H44,1)),"") | O44: =IFERROR(IF(OR(L44="",H44=""),"",L44/MAX(H44,1)),"") | P44: =IFERROR(IF(N44="","",ROUNDDOWN(装柜测算!$B$4*装柜测算!$B$6/MAX(N44,0.0001),0)),"") | Q44: =IFERROR(IF(O44="","",ROUNDDOWN(MAX(0,装柜测算!$B$5-装柜测算!$B$7)/MAX(O44,0.0001),0)),"") | R44: =IFERROR(IF(OR(P44="",Q44=""),"",MIN(P44,Q44)),"") | S44: =IF(R44="","",IF(P44<Q44,"体积限制",IF(Q44<P44,"重量限制","体积/重量接近"))) | T44: =F17
...

Sheet 产品包装信息
A1: 产品与包装信息
A2: 内部联动页：数据来自填写首页下方的产品与包装信息区，用于检查项和客户版包装信息展示。
A4: 类别 | B4: 项目 | C4: 每套用量 | D4: 产品长mm | E4: 产品宽mm | F4: 产品高mm | G4: 净重KG/件 | H4: 每箱件数 | I4: 包装长mm | J4: 包装宽mm | K4: 包装高mm | L4: 毛重KG/箱 | M4: 整箱CBM | N4: 单件CBM | O4: 单件毛重KG | P4: 体积可装件数 | Q4: 重量可装件数 | R4: 建议装柜量 | S4: 限制因素 | T4: 供应链路径 | U4: 备注 | V4: 每套CBM_helper | W4: 每套KG_helper | X4: 尼日利亚组合_helper | Y4: 中国直发_helper | Z4: 全部实物_helper | AA4: 主产品_helper | AB4: 中国发尼厂_helper
A5: =填写首页!A13 | B5: =填写首页!B13 | C5: =IF(填写首页!C40="","",填写首页!C40) | D5: =IF(填写首页!D40="","",填写首页!D40) | E5: =IF(填写首页!E40="","",填写首页!E40) | F5: =IF(填写首页!F40="","",填写首页!F40) | G5: =IF(填写首页!G40="","",填写首页!G40) | H5: =IF(填写首页!H40="","",填写首页!H40) | I5: =IF(填写首页!I40="","",填写首页!I40) | J5: =IF(填写首页!J40="","",填写首页!J40) | ... S5: =IF(填写首页!S40="","",填写首页!S40) | T5: =填写首页!F13 | U5: =IF(填写首页!U40="","",填写首页!U40) | V5: =IFERROR(C5*N5,0) | W5: =IFERROR(C5*O5,0) | X5: =IF(OR(T5="尼日利亚工厂配套后出货",T5="中国配件发尼厂后配套",T5="尼日利亚本地采购配套"),1,0) | Y5: =IF(T5="中国配件直发客户",1,0) | Z5: =IF(B5<>"",1,0) | AA5: =IF(B5="toilet bowl/pan马桶",1,0) | AB5: =IF(AND(T5="中国配件发尼厂后配套",填写首页!$E$13<>"到尼厂入库成本"),1,0)
A6: =填写首页!A14 | B6: =填写首页!B14 | C6: =IF(填写首页!C41="","",填写首页!C41) | D6: =IF(填写首页!D41="","",填写首页!D41) | E6: =IF(填写首页!E41="","",填写首页!E41) | F6: =IF(填写首页!F41="","",填写首页!F41) | G6: =IF(填写首页!G41="","",填写首页!G41) | H6: =IF(填写首页!H41="","",填写首页!H41) | I6: =IF(填写首页!I41="","",填写首页!I41) | J6: =IF(填写首页!J41="","",填写首页!J41) | ... S6: =IF(填写首页!S41="","",填写首页!S41) | T6: =填写首页!F14 | U6: =IF(填写首页!U41="","",填写首页!U41) | V6: =IFERROR(C6*N6,0) | W6: =IFERROR(C6*O6,0) | X6: =IF(OR(T6="尼日利亚工厂配套后出货",T6="中国配件发尼厂后配套",T6="尼日利亚本地采购配套"),1,0) | Y6: =IF(T6="中国配件直发客户",1,0) | Z6: =IF(B6<>"",1,0) | AA6: =IF(B6="toilet bowl/pan马桶",1,0) | AB6: =IF(AND(T6="中国配件发尼厂后配套",填写首页!$E$14<>"到尼厂入库成本"),1,0)
A7: =填写首页!A15 | B7: =填写首页!B15 | C7: =IF(填写首页!C42="","",填写首页!C42) | D7: =IF(填写首页!D42="","",填写首页!D42) | E7: =IF(填写首页!E42="","",填写首页!E42) | F7: =IF(填写首页!F42="","",填写首页!F42) | G7: =IF(填写首页!G42="","",填写首页!G42) | H7: =IF(填写首页!H42="","",填写首页!H42) | I7: =IF(填写首页!I42="","",填写首页!I42) | J7: =IF(填写首页!J42="","",填写首页!J42) | ... S7: =IF(填写首页!S42="","",填写首页!S42) | T7: =填写首页!F15 | U7: =IF(填写首页!U42="","",填写首页!U42) | V7: =IFERROR(C7*N7,0) | W7: =IFERROR(C7*O7,0) | X7: =IF(OR(T7="尼日利亚工厂配套后出货",T7="中国配件发尼厂后配套",T7="尼日利亚本地采购配套"),1,0) | Y7: =IF(T7="中国配件直发客户",1,0) | Z7: =IF(B7<>"",1,0) | AA7: =IF(B7="toilet bowl/pan马桶",1,0) | AB7: =IF(AND(T7="中国配件发尼厂后配套",填写首页!$E$15<>"到尼厂入库成本"),1,0)
A8: =填写首页!A16 | B8: =填写首页!B16 | C8: =IF(填写首页!C43="","",填写首页!C43) | D8: =IF(填写首页!D43="","",填写首页!D43) | E8: =IF(填写首页!E43="","",填写首页!E43) | F8: =IF(填写首页!F43="","",填写首页!F43) | G8: =IF(填写首页!G43="","",填写首页!G43) | H8: =IF(填写首页!H43="","",填写首页!H43) | I8: =IF(填写首页!I43="","",填写首页!I43) | J8: =IF(填写首页!J43="","",填写首页!J43) | ... S8: =IF(填写首页!S43="","",填写首页!S43) | T8: =填写首页!F16 | U8: =IF(填写首页!U43="","",填写首页!U43) | V8: =IFERROR(C8*N8,0) | W8: =IFERROR(C8*O8,0) | X8: =IF(OR(T8="尼日利亚工厂配套后出货",T8="中国配件发尼厂后配套",T8="尼日利亚本地采购配套"),1,0) | Y8: =IF(T8="中国配件直发客户",1,0) | Z8: =IF(B8<>"",1,0) | AA8: =IF(B8="toilet bowl/pan马桶",1,0) | AB8: =IF(AND(T8="中国配件发尼厂后配套",填写首页!$E$16<>"到尼厂入库成本"),1,0)
A9: =填写首页!A17 | B9: =填写首页!B17 | C9: =IF(填写首页!C44="","",填写首页!C44) | D9: =IF(填写首页!D44="","",填写首页!D44) | E9: =IF(填写首页!E44="","",填写首页!E44) | F9: =IF(填写首页!F44="","",填写首页!F44) | G9: =IF(填写首页!G44="","",填写首页!G44) | H9: =IF(填写首页!H44="","",填写首页!H44) | I9: =IF(填写首页!I44="","",填写首页!I44) | J9: =IF(填写首页!J44="","",填写首页!J44) | ... S9: =IF(填写首页!S44="","",填写首页!S44) | T9: =填写首页!F17 | U9: =IF(填写首页!U44="","",填写首页!U44) | V9: =IFERROR(C9*N9,0) | W9: =IFERROR(C9*O9,0) | X9: =IF(OR(T9="尼日利亚工厂配套后出货",T9="中国配件发尼厂后配套",T9="尼日利亚本地采购配套"),1,0) | Y9: =IF(T9="中国配件直发客户",1,0) | Z9: =IF(B9<>"",1,0) | AA9: =IF(B9="toilet bowl/pan马桶",1,0) | AB9: =IF(AND(T9="中国配件发尼厂后配套",填写首页!$E$17<>"到尼厂入库成本"),1,0)
A10: =填写首页!A18 | B10: =填写首页!B18 | C10: =IF(填写首页!C45="","",填写首页!C45) | D10: =IF(填写首页!D45="","",填写首页!D45) | E10: =IF(填写首页!E45="","",填写首页!E45) | F10: =IF(填写首页!F45="","",填写首页!F45) | G10: =IF(填写首页!G45="","",填写首页!G45) | H10: =IF(填写首页!H45="","",填写首页!H45) | I10: =IF(填写首页!I45="","",填写首页!I45) | J10: =IF(填写首页!J45="","",填写首页!J45) | ... S10: =IF(填写首页!S45="","",填写首页!S45) | T10: =填写首页!F18 | U10: =IF(填写首页!U45="","",填写首页!U45) | V10: =IFERROR(C10*N10,0) | W10: =IFERROR(C10*O10,0) | X10: =IF(OR(T10="尼日利亚工厂配套后出货",T10="中国配件发尼厂后配套",T10="尼日利亚本地采购配套"),1,0) | Y10: =IF(T10="中国配件直发客户",1,0) | Z10: =IF(B10<>"",1,0) | AA10: =IF(B10="toilet bowl/pan马桶",1,0) | AB10: =IF(AND(T10="中国配件发尼厂后配套",填写首页!$E$18<>"到尼厂入库成本"),1,0)
A11: =填写首页!A19 | B11: =填写首页!B19 | C11: =IF(填写首页!C46="","",填写首页!C46) | D11: =IF(填写首页!D46="","",填写首页!D46) | E11: =IF(填写首页!E46="","",填写首页!E46) | F11: =IF(填写首页!F46="","",填写首页!F46) | G11: =IF(填写首页!G46="","",填写首页!G46) | H11: =IF(填写首页!H46="","",填写首页!H46) | I11: =IF(填写首页!I46="","",填写首页!I46) | J11: =IF(填写首页!J46="","",填写首页!J46) | ... S11: =IF(填写首页!S46="","",填写首页!S46) | T11: =填写首页!F19 | U11: =IF(填写首页!U46="","",填写首页!U46) | V11: =IFERROR(C11*N11,0) | W11: =IFERROR(C11*O11,0) | X11: =IF(OR(T11="尼日利亚工厂配套后出货",T11="中国配件发尼厂后配套",T11="尼日利亚本地采购配套"),1,0) | Y11: =IF(T11="中国配件直发客户",1,0) | Z11: =IF(B11<>"",1,0) | AA11: =IF(B11="toilet bowl/pan马桶",1,0) | AB11: =IF(AND(T11="中国配件发尼厂后配套",填写首页!$E$19<>"到尼厂入库成本"),1,0)
A12: =填写首页!A20 | B12: =填写首页!B20 | C12: =IF(填写首页!C47="","",填写首页!C47) | D12: =IF(填写首页!D47="","",填写首页!D47) | E12: =IF(填写首页!E47="","",填写首页!E47) | F12: =IF(填写首页!F47="","",填写首页!F47) | G12: =IF(填写首页!G47="","",填写首页!G47) | H12: =IF(填写首页!H47="","",填写首页!H47) | I12: =IF(填写首页!I47="","",填写首页!I47) | J12: =IF(填写首页!J47="","",填写首页!J47) | ... S12: =IF(填写首页!S47="","",填写首页!S47) | T12: =填写首页!F20 | U12: =IF(填写首页!U47="","",填写首页!U47) | V12: =IFERROR(C12*N12,0) | W12: =IFERROR(C12*O12,0) | X12: =IF(OR(T12="尼日利亚工厂配套后出货",T12="中国配件发尼厂后配套",T12="尼日利亚本地采购配套"),1,0) | Y12: =IF(T12="中国配件直发客户",1,0) | Z12: =IF(B12<>"",1,0) | AA12: =IF(B12="toilet bowl/pan马桶",1,0) | AB12: =IF(AND(T12="中国配件发尼厂后配套",填写首页!$E$20<>"到尼厂入库成本"),1,0)
A13: =填写首页!A21 | B13: =填写首页!B21 | C13: =IF(填写首页!C48="","",填写首页!C48) | D13: =IF(填写首页!D48="","",填写首页!D48) | E13: =IF(填写首页!E48="","",填写首页!E48) | F13: =IF(填写首页!F48="","",填写首页!F48) | G13: =IF(填写首页!G48="","",填写首页!G48) | H13: =IF(填写首页!H48="","",填写首页!H48) | I13: =IF(填写首页!I48="","",填写首页!I48) | J13: =IF(填写首页!J48="","",填写首页!J48) | ... S13: =IF(填写首页!S48="","",填写首页!S48) | T13: =填写首页!F21 | U13: =IF(填写首页!U48="","",填写首页!U48) | V13: =IFERROR(C13*N13,0) | W13: =IFERROR(C13*O13,0) | X13: =IF(OR(T13="尼日利亚工厂配套后出货",T13="中国配件发尼厂后配套",T13="尼日利亚本地采购配套"),1,0) | Y13: =IF(T13="中国配件直发客户",1,0) | Z13: =IF(B13<>"",1,0) | AA13: =IF(B13="toilet bowl/pan马桶",1,0) | AB13: =IF(AND(T13="中国配件发尼厂后配套",填写首页!$E$21<>"到尼厂入库成本"),1,0)
A14: =填写首页!A22 | B14: =填写首页!B22 | C14: =IF(填写首页!C49="","",填写首页!C49) | D14: =IF(填写首页!D49="","",填写首页!D49) | E14: =IF(填写首页!E49="","",填写首页!E49) | F14: =IF(填写首页!F49="","",填写首页!F49) | G14: =IF(填写首页!G49="","",填写首页!G49) | H14: =IF(填写首页!H49="","",填写首页!H49) | I14: =IF(填写首页!I49="","",填写首页!I49) | J14: =IF(填写首页!J49="","",填写首页!J49) | ... S14: =IF(填写首页!S49="","",填写首页!S49) | T14: =填写首页!F22 | U14: =IF(填写首页!U49="","",填写首页!U49) | V14: =IFERROR(C14*N14,0) | W14: =IFERROR(C14*O14,0) | X14: =IF(OR(T14="尼日利亚工厂配套后出货",T14="中国配件发尼厂后配套",T14="尼日利亚本地采购配套"),1,0) | Y14: =IF(T14="中国配件直发客户",1,0) | Z14: =IF(B14<>"",1,0) | AA14: =IF(B14="toilet bowl/pan马桶",1,0) | AB14: =IF(AND(T14="中国配件发尼厂后配套",填写首页!$E$22<>"到尼厂入库成本"),1,0)
A15: =填写首页!A23 | B15: =填写首页!B23 | C15: =IF(填写首页!C50="","",填写首页!C50) | D15: =IF(填写首页!D50="","",填写首页!D50) | E15: =IF(填写首页!E50="","",填写首页!E50) | F15: =IF(填写首页!F50="","",填写首页!F50) | G15: =IF(填写首页!G50="","",填写首页!G50) | H15: =IF(填写首页!H50="","",填写首页!H50) | I15: =IF(填写首页!I50="","",填写首页!I50) | J15: =IF(填写首页!J50="","",填写首页!J50) | ... S15: =IF(填写首页!S50="","",填写首页!S50) | T15: =填写首页!F23 | U15: =IF(填写首页!U50="","",填写首页!U50) | V15: =IFERROR(C15*N15,0) | W15: =IFERROR(C15*O15,0) | X15: =IF(OR(T15="尼日利亚工厂配套后出货",T15="中国配件发尼厂后配套",T15="尼日利亚本地采购配套"),1,0) | Y15: =IF(T15="中国配件直发客户",1,0) | Z15: =IF(B15<>"",1,0) | AA15: =IF(B15="toilet bowl/pan马桶",1,0) | AB15: =IF(AND(T15="中国配件发尼厂后配套",填写首页!$E$23<>"到尼厂入库成本"),1,0)
A16: =填写首页!A24 | B16: =填写首页!B24 | C16: =IF(填写首页!C51="","",填写首页!C51) | D16: =IF(填写首页!D51="","",填写首页!D51) | E16: =IF(填写首页!E51="","",填写首页!E51) | F16: =IF(填写首页!F51="","",填写首页!F51) | G16: =IF(填写首页!G51="","",填写首页!G51) | H16: =IF(填写首页!H51="","",填写首页!H51) | I16: =IF(填写首页!I51="","",填写首页!I51) | J16: =IF(填写首页!J51="","",填写首页!J51) | ... S16: =IF(填写首页!S51="","",填写首页!S51) | T16: =填写首页!F24 | U16: =IF(填写首页!U51="","",填写首页!U51) | V16: =IFERROR(C16*N16,0) | W16: =IFERROR(C16*O16,0) | X16: =IF(OR(T16="尼日利亚工厂配套后出货",T16="中国配件发尼厂后配套",T16="尼日利亚本地采购配套"),1,0) | Y16: =IF(T16="中国配件直发客户",1,0) | Z16: =IF(B16<>"",1,0) | AA16: =IF(B16="toilet bowl/pan马桶",1,0) | AB16: =IF(AND(T16="中国配件发尼厂后配套",填写首页!$E$24<>"到尼厂入库成本"),1,0)

Sheet 装柜测算
A1: 装柜测算
A2: 按首页产品与包装信息估算：先算单项体积/重量限制，再按供应链路径组合成每套CBM和每套毛重，估算整柜可装套数。
A3: 柜型 | B3: 40HQ
A4: 有效容积CBM | B4: 66
A5: 限重KG | B5: 26500
A6: 装载效率 | B6: 0.92
A7: 安全重量余量KG | B7: 1000
A10: 组合场景 | B10: 每套CBM | C10: 每套毛重KG | D10: 体积可装套数 | E10: 重量可装套数 | F10: 建议装柜套数 | G10: 限制因素 | H10: 订单套数 | I10: 预计柜数 | J10: 说明
A11: 尼日利亚整套出货组合 | B11: =SUMIFS(产品包装信息!$V$5:$V$16,产品包装信息!$X$5:$X$16,1) | C11: =SUMIFS(产品包装信息!$W$5:$W$16,产品包装信息!$X$5:$X$16,1) | D11: =IF(B11=0,"",ROUNDDOWN($B$4*$B$6/MAX(B11,0.0001),0)) | E11: =IF(C11=0,"",ROUNDDOWN(MAX(0,$B$5-$B$7)/MAX(C11,0.0001),0)) | F11: =IF(OR(D11="",E11=""),"",MIN(D11,E11)) | G11: =IF(F11="","",IF(D11<E11,"体积限制",IF(E11<D11,"重量限制","体积/重量接近"))) | H11: =填写首页!$D$5 | I11: =IF(F11="","",ROUNDUP(H11/MAX(F11,1),0)) | J11: 陶瓷、发尼厂后配套配件、本地采购配套一起按尼日利亚整套出货估算。
A12: 中国配件直发组合 | B12: =SUMIFS(产品包装信息!$V$5:$V$16,产品包装信息!$Y$5:$Y$16,1) | C12: =SUMIFS(产品包装信息!$W$5:$W$16,产品包装信息!$Y$5:$Y$16,1) | D12: =IF(B12=0,"",ROUNDDOWN($B$4*$B$6/MAX(B12,0.0001),0)) | E12: =IF(C12=0,"",ROUNDDOWN(MAX(0,$B$5-$B$7)/MAX(C12,0.0001),0)) | F12: =IF(OR(D12="",E12=""),"",MIN(D12,E12)) | G12: =IF(F12="","",IF(D12<E12,"体积限制",IF(E12<D12,"重量限制","体积/重量接近"))) | H12: =填写首页!$D$5 | I12: =IF(F12="","",ROUNDUP(H12/MAX(F12,1),0)) | J12: 只估算中国直发客户的配件组合，不混入尼日利亚整套出货。
A13: 全部实物理论同柜 | B13: =SUMIFS(产品包装信息!$V$5:$V$16,产品包装信息!$Z$5:$Z$16,1) | C13: =SUMIFS(产品包装信息!$W$5:$W$16,产品包装信息!$Z$5:$Z$16,1) | D13: =IF(B13=0,"",ROUNDDOWN($B$4*$B$6/MAX(B13,0.0001),0)) | E13: =IF(C13=0,"",ROUNDDOWN(MAX(0,$B$5-$B$7)/MAX(C13,0.0001),0)) | F13: =IF(OR(D13="",E13=""),"",MIN(D13,E13)) | G13: =IF(F13="","",IF(D13<E13,"体积限制",IF(E13<D13,"重量限制","体积/重量接近"))) | H13: =填写首页!$D$5 | I13: =IF(F13="","",ROUNDUP(H13/MAX(F13,1),0)) | J13: 仅供比较：假设所有实物同柜，不代表真实出货路径。
A14: 主产品单项(toilet bowl/pan马桶) | B14: =SUMIFS(产品包装信息!$V$5:$V$16,产品包装信息!$AA$5:$AA$16,1) | C14: =SUMIFS(产品包装信息!$W$5:$W$16,产品包装信息!$AA$5:$AA$16,1) | D14: =IF(B14=0,"",ROUNDDOWN($B$4*$B$6/MAX(B14,0.0001),0)) | E14: =IF(C14=0,"",ROUNDDOWN(MAX(0,$B$5-$B$7)/MAX(C14,0.0001),0)) | F14: =IF(OR(D14="",E14=""),"",MIN(D14,E14)) | G14: =IF(F14="","",IF(D14<E14,"体积限制",IF(E14<D14,"重量限制","体积/重量接近"))) | H14: =填写首页!$D$5 | I14: =IF(F14="","",ROUNDUP(H14/MAX(F14,1),0)) | J14: 用于只有主产品单项出货时参考。
A15: 中国配件发尼厂组合 | B15: =SUMIFS(产品包装信息!$V$5:$V$16,产品包装信息!$AB$5:$AB$16,1) | C15: =SUMIFS(产品包装信息!$W$5:$W$16,产品包装信息!$AB$5:$AB$16,1) | D15: =IF(B15=0,"",ROUNDDOWN($B$4*$B$6/MAX(B15,0.0001),0)) | E15: =IF(C15=0,"",ROUNDDOWN(MAX(0,$B$5-$B$7)/MAX(C15,0.0001),0)) | F15: =IF(OR(D15="",E15=""),"",MIN(D15,E15)) | G15: =IF(F15="","",IF(D15<E15,"体积限制",IF(E15<D15,"重量限制","体积/重量接近"))) | H15: =填写首页!$D$5 | I15: =IF(F15="","",ROUNDUP(H15/MAX(F15,1),0)) | J15: 只估算中国发尼厂后配套的配件，用于中国到尼厂中转物流分摊。
A17: 单项装柜明细
A18: 项目 | B18: 供应链路径 | C18: 每套用量 | D18: 单件CBM | E18: 单件毛重KG | F18: 体积可装件数 | G18: 重量可装件数 | H18: 建议装柜量 | I18: 限制因素 | J18: 备注
A19: =产品包装信息!B5 | B19: =产品包装信息!T5 | C19: =产品包装信息!C5 | D19: =产品包装信息!N5 | E19: =产品包装信息!O5 | F19: =产品包装信息!P5 | G19: =产品包装信息!Q5 | H19: =产品包装信息!R5 | I19: =产品包装信息!S5 | J19: =产品包装信息!U5
A20: =产品包装信息!B6 | B20: =产品包装信息!T6 | C20: =产品包装信息!C6 | D20: =产品包装信息!N6 | E20: =产品包装信息!O6 | F20: =产品包装信息!P6 | G20: =产品包装信息!Q6 | H20: =产品包装信息!R6 | I20: =产品包装信息!S6 | J20: =产品包装信息!U6
A21: =产品包装信息!B7 | B21: =产品包装信息!T7 | C21: =产品包装信息!C7 | D21: =产品包装信息!N7 | E21: =产品包装信息!O7 | F21: =产品包装信息!P7 | G21: =产品包装信息!Q7 | H21: =产品包装信息!R7 | I21: =产品包装信息!S7 | J21: =产品包装信息!U7
A22: =产品包装信息!B8 | B22: =产品包装信息!T8 | C22: =产品包装信息!C8 | D22: =产品包装信息!N8 | E22: =产品包装信息!O8 | F22: =产品包装信息!P8 | G22: =产品包装信息!Q8 | H22: =产品包装信息!R8 | I22: =产品包装信息!S8 | J22: =产品包装信息!U8
A23: =产品包装信息!B9 | B23: =产品包装信息!T9 | C23: =产品包装信息!C9 | D23: =产品包装信息!N9 | E23: =产品包装信息!O9 | F23: =产品包装信息!P9 | G23: =产品包装信息!Q9 | H23: =产品包装信息!R9 | I23: =产品包装信息!S9 | J23: =产品包装信息!U9
A24: =产品包装信息!B10 | B24: =产品包装信息!T10 | C24: =产品包装信息!C10 | D24: =产品包装信息!N10 | E24: =产品包装信息!O10 | F24: =产品包装信息!P10 | G24: =产品包装信息!Q10 | H24: =产品包装信息!R10 | I24: =产品包装信息!S10 | J24: =产品包装信息!U10
A25: =产品包装信息!B11 | B25: =产品包装信息!T11 | C25: =产品包装信息!C11 | D25: =产品包装信息!N11 | E25: =产品包装信息!O11 | F25: =产品包装信息!P11 | G25: =产品包装信息!Q11 | H25: =产品包装信息!R11 | I25: =产品包装信息!S11 | J25: =产品包装信息!U11
A26: =产品包装信息!B12 | B26: =产品包装信息!T12 | C26: =产品包装信息!C12 | D26: =产品包装信息!N12 | E26: =产品包装信息!O12 | F26: =产品包装信息!P12 | G26: =产品包装信息!Q12 | H26: =产品包装信息!R12 | I26: =产品包装信息!S12 | J26: =产品包装信息!U12
A27: =产品包装信息!B13 | B27: =产品包装信息!T13 | C27: =产品包装信息!C13 | D27: =产品包装信息!N13 | E27: =产品包装信息!O13 | F27: =产品包装信息!P13 | G27: =产品包装信息!Q13 | H27: =产品包装信息!R13 | I27: =产品包装信息!S13 | J27: =产品包装信息!U13
A28: =产品包装信息!B14 | B28: =产品包装信息!T14 | C28: =产品包装信息!C14 | D28: =产品包装信息!N14 | E28: =产品包装信息!O14 | F28: =产品包装信息!P14 | G28: =产品包装信息!Q14 | H28: =产品包装信息!R14 | I28: =产品包装信息!S14 | J28: =产品包装信息!U14
A29: =产品包装信息!B15 | B29: =产品包装信息!T15 | C29: =产品包装信息!C15 | D29: =产品包装信息!N15 | E29: =产品包装信息!O15 | F29: =产品包装信息!P15 | G29: =产品包装信息!Q15 | H29: =产品包装信息!R15 | I29: =产品包装信息!S15 | J29: =产品包装信息!U15
A30: =产品包装信息!B16 | B30: =产品包装信息!T16 | C30: =产品包装信息!C16 | D30: =产品包装信息!N16 | E30: =产品包装信息!O16 | F30: =产品包装信息!P16 | G30: =产品包装信息!Q16 | H30: =产品包装信息!R16 | I30: =产品包装信息!S16 | J30: =产品包装信息!U16

Sheet 价格口径检查
A1: 价格口径检查
A3: 检查项 | B3: 状态 | C3: 处理建议 | D3: 关联位置 | E3: 说明
A4: 价格金额为空 | B4: =IF(SUMPRODUCT((填写首页!$B$13:$B$34<>"")*(填写首页!$G$13:$G$34<>"仅参考不计入")*(填写首页!$O$13:$O$34<>"公式测算")*(填写首页!$C$13:$C$34=""))>0,"报警","OK") | C4: 补齐人民币金额；物流成本选择公式测算时可不填C列 | D4: 填写首页 成本录入区
A5: 价格口径为空 | B5: =IF(COUNTIFS(填写首页!$B$13:$B$34,"<>",填写首页!$E$13:$E$34,"")>0,"报警","OK") | C5: 每个价格必须选择价格口径 | D5: 填写首页 E列
A6: 动态口径不匹配 | B6: =IF(SUMPRODUCT(--(填写首页!$D$13:$D$34="中国供应商"),--ISNA(MATCH(填写首页!$E$13:$E$34,Lists!$B$1:$B$5,0)))+SUMPRODUCT(--((填写首页!$D$13:$D$34="尼日利亚工厂")+(填写首页!$D$13:$D$34="尼日利亚本地供应商")>0),--ISNA(MATCH(填写首页!$E$13:$E$34,Lists!$A$1:$A$4,0)))>0,"报警","OK") | C6: 报价来源与价格口径必须匹配 | D6: 填写首页 D/E列 | E6: 中国供应商不能选择FOB尼日利亚港
A7: EXW价格但没有补物流 | B7: =IF(AND(COUNTIF(填写首页!$E$13:$E$34,"EXW中国供应商")>0,SUMIFS(物流参数!$J:$J,物流参数!$C:$C,"中国配件直发客户",物流参数!$K:$K,"是")+SUMIFS(物流参数!$J:$J,物流参数!$C:$C,"中国配件发尼厂后配套",物流参数!$K:$K,"是")=0),"报警","OK") | C7: EXW只含供应商裸价，需要补物流或本地费用 | D7: 物流参数
A8: FOB/入库价格重复加本地费用 | B8: =IF(AND(COUNTIFS(填写首页!$E$13:$E$34,"到尼厂入库成本",填写首页!$F$13:$F$34,"中国配件发尼厂后配套")>0,填写首页!$O$34="手动填写",N(填写首页!$C$34)>0),"报警","OK") | C8: 到尼厂入库成本已含中国段；公式测算会自动剔除中转物流，手动物流需确认未重复包含中国到尼厂费用 | D8: 填写首页 E/F列 + 物流成本行
A9: 中国直发配件被计入尼日利亚物流 | B9: =IF(COUNTIFS(填写首页!$F$13:$F$34,"中国配件直发客户",填写首页!$G$13:$G$34,"计入套装BOM")>0,"报警","OK") | C9: 中国直发客户应客户单独报价或计入独立物流，不能混入套装BOM | D9: 填写首页 F/G列
A10: CIF缺保险 | B10: =IF(AND(填写首页!$B$6="CIF目的港",N(填写首页!$B$7)<=0,N(填写首页!$D$7)<=0),"报警","OK") | C10: CIF目的港必须填写保险费率或保险金额 | D10: 填写首页 B7/D7
A11: CFR/CIF没有目的港 | B11: =IF(AND(OR(填写首页!$B$6="CFR目的港",填写首页!$B$6="CIF目的港"),填写首页!$D$6=""),"报警","OK") | C11: CFR/CIF必须有目的港 | D11: 填写首页 D6
A12: 手动确认成本未审批 | B12: =IF(SUMPRODUCT((填写首页!$E$13:$E$34="手动确认成本")*(填写首页!$O$13:$O$34<>"公式测算")*(((填写首页!$J$13:$J$34="")+(填写首页!$K$13:$K$34="")+(填写首页!$L$13:$L$34="")+(填写首页!$M$13:$M$34=""))>0))>0,"报警","OK") | C12: 内部成本例外必须填写原因、审批人、日期、有效期；物流公式测算不按手动成本审批 | D12: 填写首页 J:M列
A13: 手动项目报价未审批 | B13: =IF(AND(填写首页!$B$6="手动项目报价",OR(填写首页!$F$7="",填写首页!$H$7="",填写首页!$J$7="",填写首页!$F$8="")),"报警","OK") | C13: 客户销售报价例外必须单独审批 | D13: 填写首页 F7:J7 / F8
A14: 产品/包装信息缺失 | B14: =IF(OR(AND(填写首页!$G$13<>"仅参考不计入",填写首页!$I$13>0,OR(填写首页!$C$40="",填写首页!$D$40="",填写首页!$E$40="",填写首页!$F$40="",填写首页!$G$40="",填写首页!$H$40="",填写首页!$I$40="",填写首页!$J$40="",填写首页!$K$40="",填写首页!$L$40="")),AND(填写首页!$G$14<>"仅参考不计入",填写首页!$I$14>0,OR(填写首页!$C$41="",填写首页!$D$41="",填写首页!$E$41="",填写首页!$F$41="",填写首页!$G$41="",填写首页!$H$41="",填写首页!$I$41="",填写首页!$J$41="",填写首页!$K$41="",填写首页!$L$41="")),AND(填写首页!$G$15<>"仅参考不计入",填写首页!$I$15>0,OR(填写首页!$C$42="",填写首页!$D$42="",填写首页!$E$42="",填写首页!$F$42="",填写首页!$G$42="",填写首页!$H$42="",填写首页!$I$42="",填写首页!$J$42="",填写首页!$K$42="",填写首页!$L$42="")),AND(填写首页!$G$16<>"仅参考不计入",填写首页!$I$16>0,OR(填写首页!$C$43="",填写首页!$D$43="",填写首页!$E$43="",填写首页!$F$43="",填写首页!$G$43="",填写首页!$H$43="",填写首页!$I$43="",填写首页!$J$43="",填写首页!$K$43="",填写首页!$L$43="")),AND(填写首页!$G$17<>"仅参考不计入",填写首页!$I$17>0,OR(填写首页!$C$44="",填写首页!$D$44="",填写首页!$E$44="",填写首页!$F$44="",填写首页!$G$44="",填写首页!$H$44="",填写首页!$I$44="",填写首页!$J$44="",填写首页!$K$44="",填写首页!$L$44="")),AND(填写首页!$G$18<>"仅参考不计入",填写首页!$I$18>0,OR(填写首页!$C$45="",填写首页!$D$45="",填写首页!$E$45="",填写首页!$F$45="",填写首页!$G$45="",填写首页!$H$45="",填写首页!$I$45="",填写首页!$J$45="",填写首页!$K$45="",填写首页!$L$45="")),AND(填写首页!$G$19<>"仅参考不计入",填写首页!$I$19>0,OR(填写首页!$C$46="",填写首页!$D$46="",填写首页!$E$46="",填写首页!$F$46="",填写首页!$G$46="",填写首页!$H$46="",填写首页!$I$46="",填写首页!$J$46="",填写首页!$K$46="",填写首页!$L$46="")),AND(填写首页!$G$20<>"仅参考不计入",填写首页!$I$20>0,OR(填写首页!$C$47="",填写首页!$D$47="",填写首页!$E$47="",填写首页!$F$47="",填写首页!$G$47="",填写首页!$H$47="",填写首页!$I$47="",填写首页!$J$47="",填写首页!$K$47="",填写首页!$L$47="")),AND(填写首页!$G$21<>"仅参考不计入",填写首页!$I$21>0,OR(填写首页!$C$48="",填写首页!$D$48="",填写首页!$E$48="",填写首页!$F$48="",填写首页!$G$48="",填写首页!$H$48="",填写首页!$I$48="",填写首页!$J$48="",填写首页!$K$48="",填写首页!$L$48="")),AND(填写首页!$G$22<>"仅参考不计入",填写首页!$I$22>0,OR(填写首页!$C$49="",填写首页!$D$49="",填写首页!$E$49="",填写首页!$F$49="",填写首页!$G$49="",填写首页!$H$49="",填写首页!$I$49="",填写首页!$J$49="",填写首页!$K$49="",填写首页!$L$49="")),AND(填写首页!$G$23<>"仅参考不计入",填写首页!$I$23>0,OR(填写首页!$C$50="",填写首页!$D$50="",填写首页!$E$50="",填写首页!$F$50="",填写首页!$G$50="",填写首页!$H$50="",填写首页!$I$50="",填写首页!$J$50="",填写首页!$K$50="",填写首页!$L$50="")),AND(填写首页!$G$24<>"仅参考不计入",填写首页!$I$24>0,OR(填写首页!$C$51="",填写首页!$D$51="",填写首页!$E$51="",填写首页!$F$51="",填写首页!$G$51="",填写首页!$H$51="",填写首页!$I$51="",填写首页!$J$51="",填写首页!$K$51="",填写首页!$L$51=""))),"报警","OK") | C14: 计入报价的实物项目需要补产品尺寸、净重、每箱件数、包装尺寸和毛重 | D14: 填写首页 产品与包装信息区
A15: 成本加价率低于底线 | B15: =IF(InternalCost!$B$10<InternalCost!$D$10,"报警","OK") | C15: 复核目标价或申请审批 | D15: InternalCost
A16: DDP被当作自动报价使用 | B16: =IF(填写首页!$J$6="是","报警","OK") | C16: DDP只能作为手动项目报价并主管审批 | D16: 填写首页 J6
A17: 客户版可外发 | B17: =IF(COUNTIF($B$4:$B$16,"报警")>0,"否","是") | C17: 否时不要发送CustomerQuote | D17: CustomerQuote

Sheet BOM
A1: 类别 | B1: 项目 | C1: 生效成本RMB | D1: 价格口径 | E1: 供应链路径 | F1: 成本处理方式 | G1: 计入BOM | H1: 独立物流 | I1: 客户单独报价成本 | J1: 参与加价复核成本 | K1: 风险提示
A2: =填写首页!A13 | B2: =填写首页!B13 | C2: =填写首页!I13 | D2: =填写首页!E13 | E2: =填写首页!F13 | F2: =填写首页!G13 | G2: =IF(填写首页!G13="计入套装BOM",C2,0) | H2: =IF(填写首页!G13="计入独立物流",C2,0) | I2: =IF(填写首页!G13="客户单独报价",C2,0) | J2: =IF(填写首页!H13="是",C2,0) | K2: =IF(AND(D2="到尼厂入库成本",E2="中国配件发尼厂后配套"),"中国段已含，不再加中转物流",IF(AND(E2="中国配件直发客户",F2="计入套装BOM"),"路径冲突：直发客户不应进套装BOM",""))
A3: =填写首页!A14 | B3: =填写首页!B14 | C3: =填写首页!I14 | D3: =填写首页!E14 | E3: =填写首页!F14 | F3: =填写首页!G14 | G3: =IF(填写首页!G14="计入套装BOM",C3,0) | H3: =IF(填写首页!G14="计入独立物流",C3,0) | I3: =IF(填写首页!G14="客户单独报价",C3,0) | J3: =IF(填写首页!H14="是",C3,0) | K3: =IF(AND(D3="到尼厂入库成本",E3="中国配件发尼厂后配套"),"中国段已含，不再加中转物流",IF(AND(E3="中国配件直发客户",F3="计入套装BOM"),"路径冲突：直发客户不应进套装BOM",""))
A4: =填写首页!A15 | B4: =填写首页!B15 | C4: =填写首页!I15 | D4: =填写首页!E15 | E4: =填写首页!F15 | F4: =填写首页!G15 | G4: =IF(填写首页!G15="计入套装BOM",C4,0) | H4: =IF(填写首页!G15="计入独立物流",C4,0) | I4: =IF(填写首页!G15="客户单独报价",C4,0) | J4: =IF(填写首页!H15="是",C4,0) | K4: =IF(AND(D4="到尼厂入库成本",E4="中国配件发尼厂后配套"),"中国段已含，不再加中转物流",IF(AND(E4="中国配件直发客户",F4="计入套装BOM"),"路径冲突：直发客户不应进套装BOM",""))
A5: =填写首页!A16 | B5: =填写首页!B16 | C5: =填写首页!I16 | D5: =填写首页!E16 | E5: =填写首页!F16 | F5: =填写首页!G16 | G5: =IF(填写首页!G16="计入套装BOM",C5,0) | H5: =IF(填写首页!G16="计入独立物流",C5,0) | I5: =IF(填写首页!G16="客户单独报价",C5,0) | J5: =IF(填写首页!H16="是",C5,0) | K5: =IF(AND(D5="到尼厂入库成本",E5="中国配件发尼厂后配套"),"中国段已含，不再加中转物流",IF(AND(E5="中国配件直发客户",F5="计入套装BOM"),"路径冲突：直发客户不应进套装BOM",""))
A6: =填写首页!A17 | B6: =填写首页!B17 | C6: =填写首页!I17 | D6: =填写首页!E17 | E6: =填写首页!F17 | F6: =填写首页!G17 | G6: =IF(填写首页!G17="计入套装BOM",C6,0) | H6: =IF(填写首页!G17="计入独立物流",C6,0) | I6: =IF(填写首页!G17="客户单独报价",C6,0) | J6: =IF(填写首页!H17="是",C6,0) | K6: =IF(AND(D6="到尼厂入库成本",E6="中国配件发尼厂后配套"),"中国段已含，不再加中转物流",IF(AND(E6="中国配件直发客户",F6="计入套装BOM"),"路径冲突：直发客户不应进套装BOM",""))
A7: =填写首页!A18 | B7: =填写首页!B18 | C7: =填写首页!I18 | D7: =填写首页!E18 | E7: =填写首页!F18 | F7: =填写首页!G18 | G7: =IF(填写首页!G18="计入套装BOM",C7,0) | H7: =IF(填写首页!G18="计入独立物流",C7,0) | I7: =IF(填写首页!G18="客户单独报价",C7,0) | J7: =IF(填写首页!H18="是",C7,0) | K7: =IF(AND(D7="到尼厂入库成本",E7="中国配件发尼厂后配套"),"中国段已含，不再加中转物流",IF(AND(E7="中国配件直发客户",F7="计入套装BOM"),"路径冲突：直发客户不应进套装BOM",""))
A8: =填写首页!A19 | B8: =填写首页!B19 | C8: =填写首页!I19 | D8: =填写首页!E19 | E8: =填写首页!F19 | F8: =填写首页!G19 | G8: =IF(填写首页!G19="计入套装BOM",C8,0) | H8: =IF(填写首页!G19="计入独立物流",C8,0) | I8: =IF(填写首页!G19="客户单独报价",C8,0) | J8: =IF(填写首页!H19="是",C8,0) | K8: =IF(AND(D8="到尼厂入库成本",E8="中国配件发尼厂后配套"),"中国段已含，不再加中转物流",IF(AND(E8="中国配件直发客户",F8="计入套装BOM"),"路径冲突：直发客户不应进套装BOM",""))
A9: =填写首页!A20 | B9: =填写首页!B20 | C9: =填写首页!I20 | D9: =填写首页!E20 | E9: =填写首页!F20 | F9: =填写首页!G20 | G9: =IF(填写首页!G20="计入套装BOM",C9,0) | H9: =IF(填写首页!G20="计入独立物流",C9,0) | I9: =IF(填写首页!G20="客户单独报价",C9,0) | J9: =IF(填写首页!H20="是",C9,0) | K9: =IF(AND(D9="到尼厂入库成本",E9="中国配件发尼厂后配套"),"中国段已含，不再加中转物流",IF(AND(E9="中国配件直发客户",F9="计入套装BOM"),"路径冲突：直发客户不应进套装BOM",""))
A10: =填写首页!A21 | B10: =填写首页!B21 | C10: =填写首页!I21 | D10: =填写首页!E21 | E10: =填写首页!F21 | F10: =填写首页!G21 | G10: =IF(填写首页!G21="计入套装BOM",C10,0) | H10: =IF(填写首页!G21="计入独立物流",C10,0) | I10: =IF(填写首页!G21="客户单独报价",C10,0) | J10: =IF(填写首页!H21="是",C10,0) | K10: =IF(AND(D10="到尼厂入库成本",E10="中国配件发尼厂后配套"),"中国段已含，不再加中转物流",IF(AND(E10="中国配件直发客户",F10="计入套装BOM"),"路径冲突：直发客户不应进套装BOM",""))
A11: =填写首页!A22 | B11: =填写首页!B22 | C11: =填写首页!I22 | D11: =填写首页!E22 | E11: =填写首页!F22 | F11: =填写首页!G22 | G11: =IF(填写首页!G22="计入套装BOM",C11,0) | H11: =IF(填写首页!G22="计入独立物流",C11,0) | I11: =IF(填写首页!G22="客户单独报价",C11,0) | J11: =IF(填写首页!H22="是",C11,0) | K11: =IF(AND(D11="到尼厂入库成本",E11="中国配件发尼厂后配套"),"中国段已含，不再加中转物流",IF(AND(E11="中国配件直发客户",F11="计入套装BOM"),"路径冲突：直发客户不应进套装BOM",""))
A12: =填写首页!A23 | B12: =填写首页!B23 | C12: =填写首页!I23 | D12: =填写首页!E23 | E12: =填写首页!F23 | F12: =填写首页!G23 | G12: =IF(填写首页!G23="计入套装BOM",C12,0) | H12: =IF(填写首页!G23="计入独立物流",C12,0) | I12: =IF(填写首页!G23="客户单独报价",C12,0) | J12: =IF(填写首页!H23="是",C12,0) | K12: =IF(AND(D12="到尼厂入库成本",E12="中国配件发尼厂后配套"),"中国段已含，不再加中转物流",IF(AND(E12="中国配件直发客户",F12="计入套装BOM"),"路径冲突：直发客户不应进套装BOM",""))
A13: =填写首页!A24 | B13: =填写首页!B24 | C13: =填写首页!I24 | D13: =填写首页!E24 | E13: =填写首页!F24 | F13: =填写首页!G24 | G13: =IF(填写首页!G24="计入套装BOM",C13,0) | H13: =IF(填写首页!G24="计入独立物流",C13,0) | I13: =IF(填写首页!G24="客户单独报价",C13,0) | J13: =IF(填写首页!H24="是",C13,0) | K13: =IF(AND(D13="到尼厂入库成本",E13="中国配件发尼厂后配套"),"中国段已含，不再加中转物流",IF(AND(E13="中国配件直发客户",F13="计入套装BOM"),"路径冲突：直发客户不应进套装BOM",""))
... A23: =填写首页!A34 | B23: =填写首页!B34 | C23: =填写首页!I34 | D23: =填写首页!E34 | E23: =填写首页!F34 | F23: =填写首页!G34 | G23: =IF(填写首页!G34="计入套装BOM",C23,0) | H23: =IF(填写首页!G34="计入独立物流",C23,0) | I23: =IF(填写首页!G34="客户单独报价",C23,0) | J23: =IF(填写首页!H34="是",C23,0) | K23: =IF(AND(D23="到尼厂入库成本",E23="中国配件发尼厂后配套"),"中国段已含，不再加中转物流",IF(AND(E23="中国配件直发客户",F23="计入套装BOM"),"路径冲突：直发客户不应进套装BOM",""))
A24: 成本小计 | C24: =SUM(C2:C23) | G24: =SUM(G2:G23) | H24: =SUM(H2:H23) | I24: =SUM(I2:I23) | J24: =SUM(J2:J23)
A25: 总计 | C25: =C24 | G25: =G24 | H25: =H24 | I25: =I24 | J25: =J24

Sheet 物流参数
A1: 费用名称 | B1: 金额RMB | C1: 适用路径 | D1: 分摊方式 | E1: 分摊基数来源 | F1: 手动分摊基数 | G1: 生效分摊基数/装柜量 | H1: 预计柜数 | I1: 手动单件物流RMB | J1: 单件摊销RMB | K1: 是否启用 | L1: 备注
A2: 尼日利亚出货物流 | B2: 10000 | C2: 尼日利亚工厂配套后出货 | D2: 按柜 | E2: 按订单实际柜数摊销 | F2: ='填写首页'!$B$8 | G2: =IF($E2="手动分摊基数",N($F2),IFERROR(IF(装柜测算!$F$11="",N($F2),装柜测算!$F$11),N($F2))) | H2: =IF(AND($D2="按柜",$E2="按订单实际柜数摊销"),ROUNDUP(填写首页!$D$5/MAX($G2,1),0),"") | J2: =IF($K2<>"是",0,IF(N($I2)>0,$I2,IF($D2="按柜",IF($E2="按订单实际柜数摊销",$B2*MAX($H2,1)/MAX(填写首页!$D$5,1),$B2/MAX($G2,1)),IF($D2="按件",$B2,IF($D2="按CBM",$B2*$G2,IF($D2="按金额比例",$B2*$G2,0)))))) | K2: 是 | L2: 默认按订单实际柜数摊销；包装信息未填时回退首页默认装柜量
A3: 尼日利亚本地采购配套物流 | B3: 0 | C3: 尼日利亚本地采购配套 | D3: 按件 | E3: 手动分摊基数 | F3: 1 | G3: =IF($E3="手动分摊基数",N($F3),IFERROR(IF(装柜测算!$F$11="",N($F3),装柜测算!$F$11),N($F3))) | H3: =IF(AND($D3="按柜",$E3="按订单实际柜数摊销"),ROUNDUP(填写首页!$D$5/MAX($G3,1),0),"") | J3: =IF($K3<>"是",0,IF(N($I3)>0,$I3,IF($D3="按柜",IF($E3="按订单实际柜数摊销",$B3*MAX($H3,1)/MAX(填写首页!$D$5,1),$B3/MAX($G3,1)),IF($D3="按件",$B3,IF($D3="按CBM",$B3*$G3,IF($D3="按金额比例",$B3*$G3,0)))))) | K3: 否 | L3: 本地采购配套默认不按出口整柜重复分摊；如有本地送货/提货费再填金额并启用
A4: 中国配件直发物流 | B4: 11000 | C4: 中国配件直发客户 | D4: 按柜 | E4: 按订单实际柜数摊销 | F4: ='填写首页'!$D$8 | G4: =IF($E4="手动分摊基数",N($F4),IFERROR(IF(装柜测算!$F$12="",N($F4),装柜测算!$F$12),N($F4))) | H4: =IF(AND($D4="按柜",$E4="按订单实际柜数摊销"),ROUNDUP(填写首页!$D$5/MAX($G4,1),0),"") | J4: =IF($K4<>"是",0,IF(N($I4)>0,$I4,IF($D4="按柜",IF($E4="按订单实际柜数摊销",$B4*MAX($H4,1)/MAX(填写首页!$D$5,1),$B4/MAX($G4,1)),IF($D4="按件",$B4,IF($D4="按CBM",$B4*$G4,IF($D4="按金额比例",$B4*$G4,0)))))) | K4: 是 | L4: 中国直发客户的默认物流参数；按中国直发组合装柜量
A5: 中国到尼厂中转物流 | B5: 11000 | C5: 中国配件发尼厂后配套 | D5: 按柜 | E5: 按订单实际柜数摊销 | F5: ='填写首页'!$D$8 | G5: =IF($E5="手动分摊基数",N($F5),IFERROR(IF(装柜测算!$F$15="",N($F5),装柜测算!$F$15),N($F5))) | H5: =IF(AND($D5="按柜",$E5="按订单实际柜数摊销"),ROUNDUP(填写首页!$D$5/MAX($G5,1),0),"") | J5: =IF($K5<>"是",0,IF(N($I5)>0,$I5,IF($D5="按柜",IF($E5="按订单实际柜数摊销",$B5*MAX($H5,1)/MAX(填写首页!$D$5,1),$B5/MAX($G5,1)),IF($D5="按件",$B5,IF($D5="按CBM",$B5*$G5,IF($D5="按金额比例",$B5*$G5,0)))))) | K5: 是 | L5: 仅当配件不是到尼厂入库成本时计入；按中国发尼厂组合装柜量
A6: 尼厂到港/装柜/出口杂费 | B6: 0 | C6: 尼日利亚工厂配套后出货 | D6: 按柜 | E6: 按订单实际柜数摊销 | F6: ='填写首页'!$B$8 | G6: =IF($E6="手动分摊基数",N($F6),IFERROR(IF(装柜测算!$F$11="",N($F6),装柜测算!$F$11),N($F6))) | H6: =IF(AND($D6="按柜",$E6="按订单实际柜数摊销"),ROUNDUP(填写首页!$D$5/MAX($G6,1),0),"") | J6: =IF($K6<>"是",0,IF(N($I6)>0,$I6,IF($D6="按柜",IF($E6="按订单实际柜数摊销",$B6*MAX($H6,1)/MAX(填写首页!$D$5,1),$B6/MAX($G6,1)),IF($D6="按件",$B6,IF($D6="按CBM",$B6*$G6,IF($D6="按金额比例",$B6*$G6,0)))))) | K6: 否 | L6: 尼厂出厂成本但需补本地费用时启用

Sheet 物流测算
A1: 物流路径 | B1: 是否触发 | C1: 计入BOM物流RMB/件 | D1: 独立物流RMB/件 | E1: 客户单独物流RMB/件 | F1: 说明
A2: 尼日利亚工厂配套后出货 | B2: =SUMPRODUCT((填写首页!$F$13:$F$33=A2)*(填写首页!$G$13:$G$33<>"仅参考不计入")*(填写首页!$I$13:$I$33>0))>0 | C2: =IF(B2,SUMIFS(物流参数!$J:$J,物流参数!$C:$C,A2,物流参数!$K:$K,"是"),0) | D2: 0 | E2: 0 | F2: 陶瓷/整套尼日利亚出货物流
A3: 尼日利亚本地采购配套 | B3: =SUMPRODUCT((填写首页!$F$13:$F$33=A3)*(填写首页!$G$13:$G$33<>"仅参考不计入")*(填写首页!$I$13:$I$33>0))>0 | C3: =IF(B3,SUMIFS(物流参数!$J:$J,物流参数!$C:$C,A3,物流参数!$K:$K,"是"),0) | D3: 0 | E3: 0 | F3: 本地采购随整套发货
A4: 中国配件直发客户 | B4: =SUMPRODUCT((填写首页!$F$13:$F$33=A4)*(填写首页!$G$13:$G$33<>"仅参考不计入")*(填写首页!$I$13:$I$33>0))>0 | C4: 0 | D4: =IF(SUMPRODUCT((填写首页!$F$13:$F$33=A4)*(填写首页!$G$13:$G$33="计入独立物流")*(填写首页!$I$13:$I$33>0))>0,SUMIFS(物流参数!$J:$J,物流参数!$C:$C,A4,物流参数!$K:$K,"是"),0) | E4: =IF(SUMPRODUCT((填写首页!$F$13:$F$33=A4)*(填写首页!$G$13:$G$33="客户单独报价")*(填写首页!$I$13:$I$33>0))>0,SUMIFS(物流参数!$J:$J,物流参数!$C:$C,A4,物流参数!$K:$K,"是"),0) | F4: 中国直发物流，不混入尼日利亚整套物流
A5: 中国配件发尼厂后配套 | B5: =SUMPRODUCT((填写首页!$F$13:$F$33=A5)*(填写首页!$E$13:$E$33<>"到尼厂入库成本")*(填写首页!$G$13:$G$33<>"仅参考不计入")*(填写首页!$I$13:$I$33>0))>0 | C5: =IF(B5,SUMIFS(物流参数!$J:$J,物流参数!$C:$C,A5,物流参数!$K:$K,"是"),0) | D5: 0 | E5: 0 | F5: 仅未包含中国到尼厂费用时补中转物流
A6: 合计 | C6: =SUM(C2:C5) | D6: =SUM(D2:D5) | E6: =SUM(E2:E5)

Sheet CustomerQuote
A1: Customer Quotation
A3: Quote No. | B3: =填写首页!F4 | C3: Date | D3: =填写首页!H4 | E3: Customer | F3: =IF(填写首页!B4="","",填写首页!B4) | G3: Project | H3: =IF(填写首页!D4="","",填写首页!D4)
A4: Model | B4: =填写首页!B5 | C4: Quantity | D4: =填写首页!D5 | E4: Currency | F4: =填写首页!J4 | G4: Trade Term | H4: =IF(填写首页!B6="FOB尼日利亚港","FOB Nigeria Port",IF(填写首页!B6="CFR目的港","CFR Destination Port",IF(填写首页!B6="CIF目的港","CIF Destination Port",IF(填写首页!B6="FOB中国港","FOB China Port",IF(填写首页!B6="手动项目报价","Manual Project Quote",填写首页!B6)))))
A5: Destination Port | B5: =填写首页!D6 | C5: Display Mode | D5: =IF(填写首页!F6="套装总价","Total Set Price",IF(填写首页!F6="分项报价","Itemized Price",填写首页!F6)) | E5: Validity | G5: Remark | H5: =IF(填写首页!H8="","",填写首页!H8)
A6: Packing Dimension | B6: =IFERROR(IF(OR(INDEX(产品包装信息!$I$5:$I$25,MATCH("toilet bowl/pan马桶",产品包装信息!$B$5:$B$25,0))="",INDEX(产品包装信息!$J$5:$J$25,MATCH("toilet bowl/pan马桶",产品包装信息!$B$5:$B$25,0))="",INDEX(产品包装信息!$K$5:$K$25,MATCH("toilet bowl/pan马桶",产品包装信息!$B$5:$B$25,0))=""),"",INDEX(产品包装信息!$I$5:$I$25,MATCH("toilet bowl/pan马桶",产品包装信息!$B$5:$B$25,0))&" x "&INDEX(产品包装信息!$J$5:$J$25,MATCH("toilet bowl/pan马桶",产品包装信息!$B$5:$B$25,0))&" x "&INDEX(产品包装信息!$K$5:$K$25,MATCH("toilet bowl/pan马桶",产品包装信息!$B$5:$B$25,0))&" mm"),"") | C6: Gross Weight | D6: =IFERROR(IF(INDEX(产品包装信息!$L$5:$L$25,MATCH("toilet bowl/pan马桶",产品包装信息!$B$5:$B$25,0))="","",INDEX(产品包装信息!$L$5:$L$25,MATCH("toilet bowl/pan马桶",产品包装信息!$B$5:$B$25,0))&" kg/carton"),"") | E6: PCS/Carton | F6: =IFERROR(IF(INDEX(产品包装信息!$H$5:$H$25,MATCH("toilet bowl/pan马桶",产品包装信息!$B$5:$B$25,0))="","",INDEX(产品包装信息!$H$5:$H$25,MATCH("toilet bowl/pan马桶",产品包装信息!$B$5:$B$25,0))),"") | G6: CBM/PCS | H6: =IFERROR(IF(INDEX(产品包装信息!$N$5:$N$25,MATCH("toilet bowl/pan马桶",产品包装信息!$B$5:$B$25,0))="","",INDEX(产品包装信息!$N$5:$N$25,MATCH("toilet bowl/pan马桶",产品包装信息!$B$5:$B$25,0))),"")
A8: Line | B8: Description | C8: Origin / Path | D8: Qty | E8: Unit Price | F8: Total Amount | G8: Trade Term | H8: Remark
A9: 1 | B9: =IF(填写首页!F6="套装总价","Complete set total","Ceramic / complete set") | C9: Nigeria origin / set shipment | D9: =填写首页!D5 | E9: =IF(填写首页!F6="套装总价",IF(填写首页!J4="RMB",InternalCost!F8,InternalCost!F9),IF(填写首页!J4="RMB",InternalCost!B8,InternalCost!B9)) | F9: =D9*E9 | G9: =IF(填写首页!B6="FOB尼日利亚港","FOB Nigeria Port",IF(填写首页!B6="CFR目的港","CFR Destination Port",IF(填写首页!B6="CIF目的港","CIF Destination Port",IF(填写首页!B6="FOB中国港","FOB China Port",IF(填写首页!B6="手动项目报价","Manual Project Quote",填写首页!B6))))) | H9: =IF(填写首页!F6="套装总价","Total display; internal BOM remains separated","")
A10: 2 | B10: =IF(填写首页!F6="分项报价","China accessory separate quote","") | C10: =IF(填写首页!F6="分项报价","China origin / direct or separate path","") | D10: =IF(填写首页!F6="分项报价",填写首页!D5,"") | E10: =IF(填写首页!F6="分项报价",IF(填写首页!J4="RMB",InternalCost!D8,InternalCost!D9),"") | F10: =IF(填写首页!F6="分项报价",D10*E10,"") | G10: =IF(填写首页!F6="分项报价","FOB China Port / as agreed","")
A13: Terms
A14: 1. This customer version hides internal cost, supplier, margin and approval information.
A15: 2. CIF quotation requires insurance confirmation. DDP is not an automatic quotation term.
A16: 3. Final price is subject to product confirmation, valid quotation period, and shipping schedule.

Sheet InternalCost
A1: 内部复核版
A3: 订单数量 | B3: =填写首页!D5 | C3: 报价汇率 | D3: =填写首页!F5 | E3: 客户条款 | F3: =填写首页!B6
A4: 套装BOM成本RMB/件 | B4: =BOM!G25 | C4: 客户单独报价物料成本RMB/件 | D4: =BOM!I25 | E4: 独立物流RMB/件 | F4: =BOM!H25+物流测算!D6
A5: 套装物流成本RMB/件 | B5: =BOM!C23 | C5: 套装加价基准成本RMB/件 | D5: =MAX(B4-B5,0) | E5: 目标成本加价率 | F5: =填写首页!H5
A6: 客户单独物流RMB/件 | B6: =物流测算!E6 | C6: 客户单独加价基准成本RMB/件 | D6: =D4 | E6: 外购件成本加价率 | F6: =填写首页!H6
A7: 套装目标利润RMB/件 | B7: =D5*F5 | C7: 客户单独报价目标利润RMB/件 | D7: =D6*F6 | E7: 整体目标利润RMB/件 | F7: =B7+D7
A8: 套装目标销售RMB/件 | B8: =IFERROR(IF(填写首页!$B$6="CIF目的港",IF(填写首页!$D$7>0,D5+B5+B7+填写首页!$D$7/MAX(填写首页!$D$5,1),(D5+B5+B7)/(1-填写首页!$B$7)),D5+B5+B7),0) | C8: 客户单独报价目标销售RMB/件 | D8: =IFERROR(D6+B6+D7,0) | E8: 整体目标销售RMB/件 | F8: =B8+D8+F4
A9: 套装目标销售USD/件 | B9: =IFERROR(B8/填写首页!F5,0) | C9: 客户单独报价USD/件 | D9: =IFERROR(D8/填写首页!F5,0) | E9: 整体目标销售USD/件 | F9: =IFERROR(F8/填写首页!F5,0)
A10: 当前综合成本加价率 | B10: =IFERROR(F7/(D5+D6),0) | C10: 底线成本加价率 | D10: =填写首页!J5 | E10: 加价结论 | F10: =IF(B10<D10,"低于底线","OK")
A11: CIF保险RMB/件 | B11: =IF(填写首页!B6="CIF目的港",IF(填写首页!D7>0,填写首页!D7/MAX(填写首页!D5,1),B8*填写首页!B7),0) | C11: 报价显示方式 | D11: =填写首页!F6 | E11: 客户版可外发 | F11: =IF(COUNTIF(价格口径检查!$B:$B,"报警")>0,"否","是")

Sheet Lists
A1: 尼厂出厂成本 | B1: EXW中国供应商 | C1: 手动确认成本 | D1: 尼日利亚工厂 | E1: 尼日利亚工厂配套后出货 | F1: 计入套装BOM | G1: 是 | H1: USD | I1: FOB尼日利亚港 | J1: 套装总价 | K1: 按柜 | L1: 启用 | M1: 公式测算 | N1: 手动分摊基数
A2: 尼厂装柜成本 | B2: 送中国指定仓/进仓价 | D2: 中国供应商 | E2: 中国配件直发客户 | F2: 计入独立物流 | G2: 否 | H2: RMB | I2: CFR目的港 | J2: 分项报价 | K2: 按CBM | L2: 停用 | M2: 手动填写 | N2: 按装柜测算量
A3: FOB尼日利亚港 | B3: FOB中国港 | D3: 尼日利亚本地供应商 | E3: 中国配件发尼厂后配套 | F3: 客户单独报价 | I3: CIF目的港 | K3: 按件 | N3: 按订单实际柜数摊销
A4: 手动确认成本 | B4: 到尼厂入库成本 | D4: 手动确认 | E4: 尼日利亚本地采购配套 | F4: 仅参考不计入 | I4: FOB中国港 | K4: 按金额比例
B5: 手动确认成本 | I5: 手动项目报价
